Workbook

Sheet Sheet3

Sheet E0
A1: Div | B1: Date | C1: Time | D1: HomeTeam | E1: AwayTeam | F1: FTHG | G1: FTAG | H1: FTR | I1: HTHG | J1: HTAG | K1: HTR | L1: Referee | M1: HS | N1: AS | O1: HST | P1: AST | Q1: HF | R1: AF | S1: HC | T1: AC | U1: HY | V1: AY | W1: HR | X1: AR | Y1: B365H | Z1: B365D | AA1: B365A | AB1: BWH | AC1: BWD | AD1: BWA | AE1: BFH | AF1: BFD | AG1: BFA | AH1: PSH | AI1: PSD | AJ1: PSA | AK1: WHH | AL1: WHD | AM1: WHA | AN1: 1XBH | AO1: 1XBD | AP1: 1XBA | AQ1: MaxH | AR1: MaxD | AS1: MaxA | AT1: AvgH | AU1: AvgD | AV1: AvgA | AW1: BFEH | AX1: BFED | AY1: BFEA | AZ1: B365>2.5 | BA1: B365<2.5 | BB1: P>2.5 | BC1: P<2.5 | BD1: Max>2.5 | BE1: Max<2.5 | BF1: Avg>2.5 | BG1: Avg<2.5 | BH1: BFE>2.5 | BI1: BFE<2.5 | BJ1: AHh | BK1: B365AHH | BL1: B365AHA | BM1: PAHH | BN1: PAHA | BO1: MaxAHH | BP1: MaxAHA | BQ1: AvgAHH | BR1: AvgAHA | BS1: BFEAHH | BT1: BFEAHA | BU1: B365CH | BV1: B365CD | BW1: B365CA | BX1: BWCH | BY1: BWCD | BZ1: BWCA | CA1: BFCH | CB1: BFCD | CC1: BFCA | CD1: PSCH | CE1: PSCD | CF1: PSCA | CG1: WHCH | CH1: WHCD | CI1: WHCA | CJ1: 1XBCH | CK1: 1XBCD | CL1: 1XBCA | CM1: MaxCH | CN1: MaxCD | CO1: MaxCA | CP1: AvgCH | CQ1: AvgCD | CR1: AvgCA | CS1: BFECH | CT1: BFECD | CU1: BFECA | CV1: B365C>2.5 | CW1: B365C<2.5 | CX1: PC>2.5 | CY1: PC<2.5 | CZ1: MaxC>2.5 | DA1: MaxC<2.5 | DB1: AvgC>2.5 | DC1: AvgC<2.5 | DD1: BFEC>2.5 | DE1: BFEC<2.5 | DF1: AHCh | DG1: B365CAHH | DH1: B365CAHA | DI1: PCAHH | DJ1: PCAHA | DK1: MaxCAHH | DL1: MaxCAHA | DM1: AvgCAHH | DN1: AvgCAHA | DO1: BFECAHH | DP1: BFECAHA
A2: E0 | B2: 16/08/2024 | C2: 0.83333333 | D2: Man United | E2: Fulham | F2: 1 | G2: 0 | H2: H | I2: 0 | J2: 0 | K2: D | L2: R Jones | M2: 14 | N2: 10 | O2: 5 | P2: 2 | Q2: 12 | R2: 10 | S2: 7 | T2: 8 | U2: 2 | V2: 3 | W2: 0 | X2: 0 | Y2: 1.6 | Z2: 4.2 | AA2: 5.25 | AB2: 1.6 | AC2: 4.4 | AD2: 5.25 | AE2: 1.6 | AF2: 4.33 | AG2: 5 | AH2: 1.63 | AI2: 4.38 | AJ2: 5.3 | AK2: 1.65 | AL2: 4.2 | AM2: 5 | AN2: 1.68 | AO2: 4.32 | AP2: 5.03 | AQ2: 1.68 | AR2: 4.5 | AS2: 5.5 | AT2: 1.62 | AU2: 4.36 | AV2: 5.15 | AW2: 1.66 | AX2: 4.5 | AY2: 5.6 | AZ2: 1.53 | BA2: 2.5 | BB2: 1.56 | BC2: 2.56 | BD2: 1.57 | BE2: 2.6 | BF2: 1.53 | BG2: 2.52 | BH2: 1.59 | BI2: 2.64 | BJ2: -1 | BK2: 2.05 | BL2: 1.88 | BM2: 2.07 | BN2: 1.86 | BO2: 2.07 | BP2: 1.89 | BQ2: 2.03 | BR2: 1.85 | BS2: 2.1 | BT2: 1.88 | BU2: 1.67 | BV2: 4.1 | BW2: 5 | BX2: 1.65 | BY2: 4.2 | BZ2: 4.8 | CA2: 1.62 | CB2: 4 | CC2: 5 | CD2: 1.65 | CE2: 4.23 | CF2: 5.28 | CG2: 1.6 | CH2: 4.2 | CI2: 5.5 | CJ2: 1.66 | CK2: 4.15 | CL2: 5.33 | CM2: 1.7 | CN2: 4.33 | CO2: 5.5 | CP2: 1.66 | CQ2: 4.2 | CR2: 5.02 | CS2: 1.72 | CT2: 4.2 | CU2: 5.4 | CV2: 1.62 | CW2: 2.3 | CX2: 1.63 | CY2: 2.38 | CZ2: 1.66 | DA2: 2.45 | DB2: 1.61 | DC2: 2.37 | DD2: 1.68 | DE2: 2.46 | DF2: -0.75 | DG2: 1.86 | DH2: 2.07 | DI2: 1.83 | DJ2: 2.11 | DK2: 1.88 | DL2: 2.11 | DM2: 1.82 | DN2: 2.05 | DO2: 1.9 | DP2: 2.08
A3: E0 | B3: 17/08/2024 | C3: 0.52083333 | D3: Ipswich | E3: Liverpool | F3: 0 | G3: 2 | H3: A | I3: 0 | J3: 0 | K3: D | L3: T Robinson | M3: 7 | N3: 18 | O3: 2 | P3: 5 | Q3: 9 | R3: 18 | S3: 2 | T3: 10 | U3: 3 | V3: 1 | W3: 0 | X3: 0 | Y3: 8.5 | Z3: 5.5 | AA3: 1.33 | AB3: 7.5 | AC3: 5.5 | AD3: 1.36 | AE3: 8.5 | AF3: 5.5 | AG3: 1.33 | AH3: 8.18 | AI3: 5.84 | AJ3: 1.34 | AK3: 8.5 | AL3: 5.5 | AM3: 1.33 | AN3: 8.6 | AO3: 5.85 | AP3: 1.35 | AQ3: 9 | AR3: 6.1 | AS3: 1.37 | AT3: 8.28 | AU3: 5.76 | AV3: 1.34 | AW3: 9.4 | AX3: 6.2 | AY3: 1.36 | AZ3: 1.4 | BA3: 3 | BB3: 1.41 | BC3: 3 | BD3: 1.43 | BE3: 3.07 | BF3: 1.41 | BG3: 2.94 | BH3: 1.45 | BI3: 3.15 | BJ3: 1.5 | BK3: 2.02 | BL3: 1.91 | BM3: 1.99 | BN3: 1.92 | BO3: 2.02 | BP3: 1.95 | BQ3: 1.97 | BR3: 1.9 | BS3: 2.04 | BT3: 1.93 | BU3: 8 | BV3: 5.75 | BW3: 1.33 | BX3: 8 | BY3: 5.75 | BZ3: 1.34 | CA3: 7.5 | CB3: 5.5 | CC3: 1.33 | CD3: 8.14 | CE3: 6.09 | CF3: 1.34 | CG3: 8 | CH3: 5.5 | CI3: 1.35 | CJ3: 8.57 | CK3: 5.85 | CL3: 1.34 | CM3: 8.57 | CN3: 6.25 | CO3: 1.39 | CP3: 7.87 | CQ3: 5.81 | CR3: 1.35 | CS3: 8.6 | CT3: 6.2 | CU3: 1.37 | CV3: 1.36 | CW3: 3.2 | CX3: 1.37 | CY3: 3.3 | CZ3: 1.4 | DA3: 3.38 | DB3: 1.37 | DC3: 3.18 | DD3: 1.4 | DE3: 3.4 | DF3: 1.5 | DG3: 2.05 | DH3: 1.88 | DI3: 2.04 | DJ3: 1.9 | DK3: 2.2 | DL3: 2 | DM3: 1.99 | DN3: 1.88 | DO3: 2.04 | DP3: 1.93
A4: E0 | B4: 17/08/2024 | C4: 0.625 | D4: Arsenal | E4: Wolves | F4: 2 | G4: 0 | H4: H | I4: 1 | J4: 0 | K4: H | L4: J Gillett | M4: 18 | N4: 9 | O4: 6 | P4: 3 | Q4: 17 | R4: 14 | S4: 8 | T4: 2 | U4: 2 | V4: 2 | W4: 0 | X4: 0 | Y4: 1.18 | Z4: 7.5 | AA4: 13 | AB4: 1.2 | AC4: 7.5 | AD4: 13.5 | AE4: 1.15 | AF4: 8 | AG4: 16 | AH4: 1.16 | AI4: 8.56 | AJ4: 16.22 | AK4: 1.18 | AL4: 7 | AM4: 17 | AN4: 1.2 | AO4: 7.65 | AP4: 16 | AQ4: 1.2 | AR4: 9.1 | AS4: 18 | AT4: 1.18 | AU4: 7.86 | AV4: 15.87 | AW4: 1.19 | AX4: 9 | AY4: 18 | AZ4: 1.44 | BA4: 2.75 | BB4: 1.46 | BC4: 2.79 | BD4: 1.5 | BE4: 2.82 | BF4: 1.46 | BG4: 2.7 | BH4: 1.53 | BI4: 2.84 | BJ4: -2 | BK4: 1.93 | BL4: 2 | BM4: 1.88 | BN4: 2 | BO4: 1.97 | BP4: 2 | BQ4: 1.9 | BR4: 1.96 | BS4: 1.94 | BT4: 2 | BU4: 1.14 | BV4: 8.5 | BW4: 15 | BX4: 1.16 | BY4: 8.5 | BZ4: 18 | CA4: 1.13 | CB4: 8.5 | CC4: 17 | CD4: 1.15 | CE4: 9.05 | CF4: 18.76 | CG4: 1.15 | CH4: 8 | CI4: 19 | CJ4: 1.16 | CK4: 9.39 | CL4: 16.6 | CM4: 1.17 | CN4: 9.4 | CO4: 21 | CP4: 1.15 | CQ4: 8.62 | CR4: 18.11 | CS4: 1.17 | CT4: 9.4 | CU4: 21 | CV4: 1.4 | CW4: 3 | CX4: 1.41 | CY4: 2.98 | CZ4: 1.45 | DA4: 3 | DB4: 1.42 | DC4: 2.93 | DD4: 1.44 | DE4: 3.2 | DF4: -2.25 | DG4: 2.02 | DH4: 1.91 | DI4: 2 | DJ4: 1.9 | DK4: 2.05 | DL4: 1.93 | DM4: 1.99 | DN4: 1.87 | DO4: 2.02 | DP4: 1.96
A5: E0 | B5: 17/08/2024 | C5: 0.625 | D5: Everton | E5: Brighton | F5: 0 | G5: 3 | H5: A | I5: 0 | J5: 1 | K5: A | L5: S Hooper | M5: 9 | N5: 10 | O5: 1 | P5: 5 | Q5: 8 | R5: 8 | S5: 1 | T5: 5 | U5: 1 | V5: 1 | W5: 1 | X5: 0 | Y5: 2.63 | Z5: 3.3 | AA5: 2.63 | AB5: 2.65 | AC5: 3.4 | AD5: 2.6 | AE5: 2.7 | AF5: 3.4 | AG5: 2.63 | AH5: 2.73 | AI5: 3.36 | AJ5: 2.71 | AK5: 2.6 | AL5: 3.5 | AM5: 2.7 | AN5: 2.68 | AO5: 3.66 | AP5: 2.63 | AQ5: 2.76 | AR5: 3.66 | AS5: 2.78 | AT5: 2.67 | AU5: 3.41 | AV5: 2.68 | AW5: 2.78 | AX5: 3.5 | AY5: 2.78 | AZ5: 1.8 | BA5: 2 | BB5: 1.83 | BC5: 2.05 | BD5: 1.85 | BE5: 2.08 | BF5: 1.81 | BG5: 2.04 | BH5: 1.88 | BI5: 2.08 | BJ5: 0 | BK5: 1.96 | BL5: 1.97 | BM5: 1.96 | BN5: 1.94 | BO5: 1.97 | BP5: 1.97 | BQ5: 1.94 | BR5: 1.94 | BS5: 1.99 | BT5: 1.99 | BU5: 3.1 | BV5: 3.4 | BW5: 2.3 | BX5: 3 | BY5: 3.4 | BZ5: 2.37 | CA5: 3 | CB5: 3.3 | CC5: 2.3 | CD5: 3.15 | CE5: 3.41 | CF5: 2.4 | CG5: 3.1 | CH5: 3.3 | CI5: 2.4 | CJ5: 3.16 | CK5: 3.47 | CL5: 2.34 | CM5: 3.16 | CN5: 3.5 | CO5: 2.45 | CP5: 3.06 | CQ5: 3.4 | CR5: 2.38 | CS5: 3.15 | CT5: 3.55 | CU5: 2.46 | CV5: 1.93 | CW5: 1.97 | CX5: 1.93 | CY5: 1.97 | CZ5: 1.95 | DA5: 2 | DB5: 1.89 | DC5: 1.96 | DD5: 1.94 | DE5: 2.04 | DF5: 0.25 | DG5: 1.87 | DH5: 2.06 | DI5: 1.86 | DJ5: 2.07 | DK5: 1.92 | DL5: 2.1 | DM5: 1.83 | DN5: 2.04 | DO5: 1.88 | DP5: 2.11
A6: E0 | B6: 17/08/2024 | C6: 0.625 | D6: Newcastle | E6: Southampton | F6: 1 | G6: 0 | H6: H | I6: 1 | J6: 0 | K6: H | L6: C Pawson | M6: 3 | N6: 19 | O6: 1 | P6: 4 | Q6: 15 | R6: 16 | S6: 3 | T6: 12 | U6: 2 | V6: 4 | W6: 1 | X6: 0 | Y6: 1.36 | Z6: 5.25 | AA6: 8 | AB6: 1.35 | AC6: 5.5 | AD6: 7.75 | AE6: 1.33 | AF6: 5.5 | AG6: 8.5 | AH6: 1.35 | AI6: 5.7 | AJ6: 8.25 | AK6: 1.35 | AL6: 5.5 | AM6: 8 | AN6: 1.37 | AO6: 5.74 | AP6: 8.1 | AQ6: 1.37 | AR6: 5.9 | AS6: 8.6 | AT6: 1.35 | AU6: 5.62 | AV6: 8.1 | AW6: 1.37 | AX6: 6 | AY6: 9.2 | AZ6: 1.4 | BA6: 3 | BB6: 1.4 | BC6: 3.09 | BD6: 1.42 | BE6: 3.12 | BF6: 1.4 | BG6: 3.01 | BH6: 1.43 | BI6: 3.15 | BJ6: -1.5 | BK6: 1.98 | BL6: 1.95 | BM6: 1.94 | BN6: 1.96 | BO6: 1.99 | BP6: 1.98 | BQ6: 1.93 | BR6: 1.93 | BS6: 1.94 | BT6: 2.01 | BU6: 1.4 | BV6: 5 | BW6: 7 | BX6: 1.39 | BY6: 5.25 | BZ6: 7.25 | CA6: 1.36 | CB6: 5 | CC6: 7.5 | CD6: 1.42 | CE6: 5.3 | CF6: 7.26 | CG6: 1.4 | CH6: 5 | CI6: 7.5 | CJ6: 1.39 | CK6: 5.34 | CL6: 7.9 | CM6: 1.44 | CN6: 5.75 | CO6: 8 | CP6: 1.39 | CQ6: 5.27 | CR6: 7.33 | CS6: 1.43 | CT6: 5.5 | CU6: 8.2 | CV6: 1.44 | CW6: 2.75 | CX6: 1.46 | CY6: 2.85 | CZ6: 1.46 | DA6: 3.05 | DB6: 1.43 | DC6: 2.84 | DD6: 1.49 | DE6: 2.98 | DF6: -1.25 | DG6: 1.87 | DH6: 2.06 | DI6: 1.88 | DJ6: 2.06 | DK6: 1.89 | DL6: 2.1 | DM6: 1.82 | DN6: 2.05 | DO6: 1.89 | DP6: 2.1
A7: E0 | B7: 17/08/2024 | C7: 0.625 | D7: Nott'm Forest | E7: Bournemouth | F7: 1 | G7: 1 | H7: D | I7: 1 | J7: 0 | K7: H | L7: M Oliver | M7: 14 | N7: 13 | O7: 8 | P7: 4 | Q7: 17 | R7: 8 | S7: 2 | T7: 6 | U7: 1 | V7: 3 | W7: 0 | X7: 0 | Y7: 2.45 | Z7: 3.5 | AA7: 2.8 | AB7: 2.45 | AC7: 3.5 | AD7: 2.8 | AE7: 2.45 | AF7: 3.5 | AG7: 2.88 | AH7: 2.47 | AI7: 3.42 | AJ7: 2.97 | AK7: 2.5 | AL7: 3.5 | AM7: 2.8 | AN7: 2.46 | AO7: 3.7 | AP7: 2.87 | AQ7: 2.51 | AR7: 3.7 | AS7: 3 | AT7: 2.45 | AU7: 3.49 | AV7: 2.89 | AW7: 2.54 | AX7: 3.6 | AY7: 3 | AZ7: 1.73 | BA7: 2.1 | BB7: 1.79 | BC7: 2.11 | BD7: 1.81 | BE7: 2.14 | BF7: 1.77 | BG7: 2.08 | BH7: 1.83 | BI7: 2.16 | BJ7: 0 | BK7: 1.82 | BL7: 2.11 | BM7: 1.78 | BN7: 2.14 | BO7: 1.83 | BP7: 2.14 | BQ7: 1.8 | BR7: 2.09 | BS7: 1.83 | BT7: 2.17 | BU7: 2.2 | BV7: 3.4 | BW7: 3.25 | BX7: 2.2 | BY7: 3.4 | BZ7: 3.25 | CA7: 2.2 | CB7: 3.3 | CC7: 3.25 | CD7: 2.24 | CE7: 3.5 | CF7: 3.37 | CG7: 2.25 | CH7: 3.4 | CI7: 3.25 | CJ7: 2.26 | CK7: 3.49 | CL7: 3.33 | CM7: 2.38 | CN7: 3.55 | CO7: 3.37 | CP7: 2.25 | CQ7: 3.44 | CR7: 3.23 | CS7: 2.3 | CT7: 3.5 | CU7: 3.5 | CV7: 1.89 | CW7: 2.01 | CX7: 1.89 | CY7: 2.02 | CZ7: 1.93 | DA7: 2.04 | DB7: 1.87 | DC7: 1.96 | DD7: 1.91 | DE7: 2.08 | DF7: -0.25 | DG7: 1.94 | DH7: 1.99 | DI7: 1.94 | DJ7: 1.98 | DK7: 2.05 | DL7: 2 | DM7: 1.93 | DN7: 1.93 | DO7: 1.96 | DP7: 2.02
A8: E0 | B8: 17/08/2024 | C8: 0.72916667 | D8: West Ham | E8: Aston Villa | F8: 1 | G8: 2 | H8: A | I8: 1 | J8: 1 | K8: D | L8: T Harrington | M8: 14 | N8: 15 | O8: 3 | P8: 3 | Q8: 18 | R8: 11 | S8: 5 | T8: 3 | U8: 1 | V8: 2 | W8: 0 | X8: 0 | Y8: 2.45 | Z8: 3.6 | AA8: 2.75 | AB8: 2.45 | AC8: 3.6 | AD8: 2.7 | AE8: 2.4 | AF8: 3.6 | AG8: 2.8 | AH8: 2.49 | AI8: 3.65 | AJ8: 2.8 | AK8: 2.4 | AL8: 3.75 | AM8: 2.75 | AN8: 2.42 | AO8: 3.91 | AP8: 2.81 | AQ8: 2.49 | AR8: 3.91 | AS8: 2.87 | AT8: 2.44 | AU8: 3.69 | AV8: 2.79 | AW8: 2.5 | AX8: 3.75 | AY8: 2.94 | AZ8: 1.57 | BA8: 2.38 | BB8: 1.59 | BC8: 2.46 | BD8: 1.59 | BE8: 2.52 | BF8: 1.57 | BG8: 2.43 | BH8: 1.63 | BI8: 2.52 | BJ8: -0.25 | BK8: 2.08 | BL8: 1.73 | BM8: 2.16 | BN8: 1.76 | BO8: 2.16 | BP8: 1.82 | BQ8: 2.1 | BR8: 1.78 | BS8: 2.17 | BT8: 1.84 | BU8: 2.4 | BV8: 3.5 | BW8: 2.8 | BX8: 2.5 | BY8: 3.5 | BZ8: 2.75 | CA8: 2.38 | CB8: 3.4 | CC8: 2.8 | CD8: 2.54 | CE8: 3.51 | CF8: 2.86 | CG8: 2.5 | CH8: 3.5 | CI8: 2.8 | CJ8: 2.56 | CK8: 3.6 | CL8: 2.77 | CM8: 2.56 | CN8: 3.6 | CO8: 2.91 | CP8: 2.47 | CQ8: 3.51 | CR8: 2.83 | CS8: 2.54 | CT8: 3.65 | CU8: 2.98 | CV8: 1.73 | CW8: 2.1 | CX8: 1.72 | CY8: 2.21 | CZ8: 1.73 | DA8: 2.32 | DB8: 1.68 | DC8: 2.22 | DD8: 1.74 | DE8: 2.32 | DF8: 0 | DG8: 1.83 | DH8: 2.1 | DI8: 1.85 | DJ8: 2.09 | DK8: 1.86 | DL8: 2.14 | DM8: 1.82 | DN8: 2.08 | DO8: 1.84 | DP8: 2.18
A9: E0 | B9: 18/08/2024 | C9: 0.58333333 | D9: Brentford | E9: Crystal Palace | F9: 2 | G9: 1 | H9: H | I9: 1 | J9: 0 | K9: H | L9: S Barrott | M9: 9 | N9: 14 | O9: 5 | P9: 6 | Q9: 6 | R9: 15 | S9: 4 | T9: 7 | U9: 1 | V9: 5 | W9: 0 | X9: 0 | Y9: 2.4 | Z9: 3.4 | AA9: 2.9 | AB9: 2.4 | AC9: 3.4 | AD9: 2.87 | AE9: 2.45 | AF9: 3.4 | AG9: 2.88 | AH9: 2.5 | AI9: 3.4 | AJ9: 2.95 | AK9: 2.45 | AL9: 3.5 | AM9: 2.88 | AN9: 2.47 | AO9: 3.66 | AP9: 2.88 | AQ9: 2.52 | AR9: 3.66 | AS9: 2.99 | AT9: 2.46 | AU9: 3.44 | AV9: 2.9 | AW9: 2.54 | AX9: 3.55 | AY9: 3 | AZ9: 1.8 | BA9: 2 | BB9: 1.83 | BC9: 2.05 | BD9: 1.85 | BE9: 2.08 | BF9: 1.81 | BG9: 2.03 | BH9: 1.84 | BI9: 2.14 | BJ9: -0.25 | BK9: 2.11 | BL9: 1.82 | BM9: 2.15 | BN9: 1.78 | BO9: 2.15 | BP9: 1.82 | BQ9: 2.1 | BR9: 1.78 | BS9: 2.18 | BT9: 1.83 | BU9: 2.88 | BV9: 3.2 | BW9: 2.55 | BX9: 2.8 | BY9: 3.2 | BZ9: 2.6 | CA9: 2.8 | CB9: 3.25 | CC9: 2.63 | CD9: 2.92 | CE9: 3.24 | CF9: 2.66 | CG9: 3 | CH9: 3.2 | CI9: 2.5 | CJ9: 2.98 | CK9: 3.3 | CL9: 2.56 | CM9: 3 | CN9: 3.4 | CO9: 2.72 | CP9: 2.85 | CQ9: 3.28 | CR9: 2.62 | CS9: 2.94 | CT9: 3.35 | CU9: 2.74 | CV9: 2.07 | CW9: 1.83 | CX9: 2.09 | CY9: 1.83 | CZ9: 2.09 | DA9: 1.91 | DB9: 2 | DC9: 1.85 | DD9: 2.1 | DE9: 1.89 | DF9: 0 | DG9: 2.07 | DH9: 1.86 | DI9: 2.06 | DJ9: 1.88 | DK9: 2.11 | DL9: 1.88 | DM9: 2.05 | DN9: 1.85 | DO9: 2.07 | DP9: 1.92
A10: E0 | B10: 18/08/2024 | C10: 0.6875 | D10: Chelsea | E10: Man City | F10: 0 | G10: 2 | H10: A | I10: 0 | J10: 1 | K10: A | L10: A Taylor | M10: 10 | N10: 11 | O10: 3 | P10: 5 | Q10: 12 | R10: 9 | S10: 4 | T10: 3 | U10: 1 | V10: 1 | W10: 0 | X10: 0 | Y10: 4.1 | Z10: 3.9 | AA10: 1.8 | AB10: 3.9 | AC10: 4.1 | AD10: 1.82 | AE10: 4.1 | AF10: 3.9 | AG10: 1.8 | AH10: 4.19 | AI10: 3.93 | AJ10: 1.84 | AK10: 4 | AL10: 4 | AM10: 1.83 | AN10: 4.02 | AO10: 4.22 | AP10: 1.85 | AQ10: 4.3 | AR10: 4.22 | AS10: 1.88 | AT10: 4.05 | AU10: 4 | AV10: 1.83 | AW10: 4.3 | AX10: 4.1 | AY10: 1.87 | AZ10: 1.5 | BA10: 2.63 | BB10: 1.52 | BC10: 2.62 | BD10: 1.53 | BE10: 2.69 | BF10: 1.5 | BG10: 2.59 | BH10: 1.56 | BI10: 2.68 | BJ10: 0.5 | BK10: 2.07 | BL10: 1.86 | BM10: 2.06 | BN10: 1.85 | BO10: 2.08 | BP10: 1.86 | BQ10: 2.03 | BR10: 1.83 | BS10: 2.12 | BT10: 1.87 | BU10: 3.6 | BV10: 3.9 | BW10: 1.95 | BX10: 3.6 | BY10: 3.75 | BZ10: 1.98 | CA10: 3.6 | CB10: 3.8 | CC10: 2 | CD10: 3.86 | CE10: 3.91 | CF10: 1.97 | CG10: 3.5 | CH10: 3.9 | CI10: 2 | CJ10: 3.89 | CK10: 3.96 | CL10: 1.92 | CM10: 3.89 | CN10: 3.96 | CO10: 2.05 | CP10: 3.64 | CQ10: 3.83 | CR10: 1.98 | CS10: 3.75 | CT10: 3.9 | CU10: 2.06 | CV10: 1.57 | CW10: 2.38 | CX10: 1.58 | CY10: 2.51 | CZ10: 1.61 | DA10: 2.52 | DB10: 1.56 | DC10: 2.45 | DD10: 1.62 | DE10: 2.6 | DF10: 0.5 | DG10: 1.94 | DH10: 1.99 | DI10: 1.96 | DJ10: 1.97 | DK10: 1.96 | DL10: 2 | DM10: 1.9 | DN10: 1.96 | DO10: 1.93 | DP10: 2.07
A11: E0 | B11: 19/08/2024 | C11: 0.83333333 | D11: Leicester | E11: Tottenham | F11: 1 | G11: 1 | H11: D | I11: 0 | J11: 1 | K11: A | L11: C Kavanagh | M11: 7 | N11: 15 | O11: 3 | P11: 7 | Q11: 11 | R11: 12 | S11: 2 | T11: 13 | U11: 1 | V11: 1 | W11: 0 | X11: 0 | Y11: 5 | Z11: 4.33 | AA11: 1.62 | AB11: 5 | AC11: 4.33 | AD11: 1.63 | AE11: 5 | AF11: 4.33 | AG11: 1.57 | AH11: 5.09 | AI11: 4.39 | AJ11: 1.63 | AK11: 5 | AL11: 4.33 | AM11: 1.65 | AN11: 4.98 | AO11: 4.52 | AP11: 1.66 | AQ11: 5.3 | AR11: 4.52 | AS11: 1.67 | AT11: 5.01 | AU11: 4.37 | AV11: 1.63 | AW11: 5.4 | AX11: 4.6 | AY11: 1.65 | AZ11: 1.53 | BA11: 2.5 | BB11: 1.53 | BC11: 2.61 | BD11: 1.55 | BE11: 2.63 | BF11: 1.52 | BG11: 2.54 | BH11: 1.56 | BI11: 2.7 | BJ11: 1 | BK11: 1.86 | BL11: 2.07 | BM11: 1.86 | BN11: 2.05 | BO11: 1.86 | BP11: 2.09 | BQ11: 1.83 | BR11: 2.03 | BS11: 1.91 | BT11: 2.06 | BU11: 4.5 | BV11: 4.2 | BW11: 1.7 | BX11: 4.33 | BY11: 4.2 | BZ11: 1.72 | CA11: 4.33 | CB11: 4.1 | CC11: 1.7 | CD11: 4.64 | CE11: 4.33 | CF11: 1.71 | CG11: 4.6 | CH11: 4.2 | CI11: 1.7 | CJ11: 4.79 | CK11: 4.27 | CL11: 1.7 | CM11: 4.9 | CN11: 4.4 | CO11: 1.74 | CP11: 4.57 | CQ11: 4.23 | CR11: 1.71 | CS11: 4.7 | CT11: 4.4 | CU11: 1.76 | CV11: 1.57 | CW11: 2.38 | CX11: 1.54 | CY11: 2.61 | CZ11: 1.57 | DA11: 2.62 | DB11: 1.54 | DC11: 2.52 | DD11: 1.58 | DE11: 2.7 | DF11: 0.75 | DG11: 2.03 | DH11: 1.9 | DI11: 2.02 | DJ11: 1.91 | DK11: 2.06 | DL11: 1.92 | DM11: 1.99 | DN11: 1.87 | DO11: 2.03 | DP11: 1.96
A12: E0 | B12: 24/08/2024 | C12: 0.52083333 | D12: Brighton | E12: Man United | F12: 2 | G12: 1 | H12: H | I12: 1 | J12: 0 | K12: H | L12: C Pawson | M12: 14 | N12: 11 | O12: 5 | P12: 4 | Q12: 9 | R12: 13 | S12: 4 | T12: 4 | U12: 1 | V12: 2 | W12: 0 | X12: 0 | Y12: 2.5 | Z12: 3.7 | AA12: 2.63 | AB12: 2.5 | AC12: 3.75 | AD12: 2.6 | AE12: 2.5 | AF12: 3.75 | AG12: 2.7 | AH12: 2.51 | AI12: 3.66 | AJ12: 2.76 | AK12: 2.5 | AL12: 3.7 | AM12: 2.7 | AN12: 2.54 | AO12: 3.87 | AP12: 2.68 | AQ12: 2.54 | AR12: 3.87 | AS12: 2.79 | AT12: 2.5 | AU12: 3.72 | AV12: 2.69 | AW12: 2.58 | AX12: 3.9 | AY12: 2.8 | AZ12: 1.57 | BA12: 2.38 | BB12: 1.6 | BC12: 2.45 | BD12: 1.63 | BE12: 2.5 | BF12: 1.58 | BG12: 2.42 | BH12: 1.62 | BI12: 2.5 | BJ12: 0 | BK12: 1.86 | BL12: 2.04 | BM12: 1.86 | BN12: 2.05 | BO12: 1.91 | BP12: 2.06 | BQ12: 1.88 | BR12: 2.01 | BS12: 1.91 | BT12: 2.08 | BU12: 2.3 | BV12: 3.8 | BW12: 2.88 | BX12: 2.3 | BY12: 3.7 | BZ12: 2.85 | CA12: 2.3 | CB12: 3.6 | CC12: 2.8 | CD12: 2.42 | CE12: 3.76 | CF12: 2.86 | CG12: 2.38 | CH12: 3.6 | CI12: 2.88 | CJ12: 2.57 | CK12: 3.85 | CL12: 2.63 | CM12: 2.57 | CN12: 3.9 | CO12: 2.96 | CP12: 2.41 | CQ12: 3.72 | CR12: 2.81 | CS12: 2.48 | CT12: 3.85 | CU12: 2.94 | CV12: 1.53 | CW12: 2.5 | CX12: 1.54 | CY12: 2.6 | CZ12: 1.6 | DA12: 2.62 | DB12: 1.54 | DC12: 2.52 | DD12: 1.58 | DE12: 2.7 | DF12: -0.25 | DG12: 2.07 | DH12: 1.86 | DI12: 2.12 | DJ12: 1.83 | DK12: 2.2 | DL12: 1.86 | DM12: 2.09 | DN12: 1.79 | DO12: 2.15 | DP12: 1.85
A13: E0 | B13: 24/08/2024 | C13: 0.625 | D13: Crystal Palace | E13: West Ham | F13: 0 | G13: 2 | H13: A | I13: 0 | J13: 0 | K13: D | L13: R Jones | M13: 14 | N13: 18 | O13: 2 | P13: 3 | Q13: 9 | R13: 17 | S13: 3 | T13: 3 | U13: 1 | V13: 1 | W13: 0 | X13: 0 | Y13: 2.15 | Z13: 3.6 | AA13: 3.2 | AB13: 2.15 | AC13: 3.5 | AD13: 3.2 | AE13: 2.15 | AF13: 3.5 | AG13: 3.3 | AH13: 2.17 | AI13: 3.68 | AJ13: 3.33 | AK13: 2.2 | AL13: 3.5 | AM13: 3.3 | AN13: 2.19 | AO13: 3.76 | AP13: 3.31 | AQ13: 2.21 | AR13: 3.76 | AS13: 3.36 | AT13: 2.17 | AU13: 3.63 | AV13: 3.25 | AW13: 2.24 | AX13: 3.7 | AY13: 3.45 | AZ13: 1.73 | BA13: 2.1 | BB13: 1.76 | BC13: 2.15 | BD13: 1.81 | BE13: 2.19 | BF13: 1.76 | BG13: 2.1 | BH13: 1.82 | BI13: 2.18 | BJ13: -0.25 | BK13: 1.91 | BL13: 1.99 | BM13: 1.88 | BN13: 2.02 | BO13: 1.94 | BP13: 2.02 | BQ13: 1.88 | BR13: 1.98 | BS13: 1.94 | BT13: 2.05 | BU13: 1.95 | BV13: 3.9 | BW13: 3.7 | BX13: 1.93 | BY13: 3.7 | BZ13: 3.75 | CA13: 1.91 | CB13: 3.8 | CC13: 3.9 | CD13: 1.97 | CE13: 3.84 | CF13: 3.84 | CG13: 1.95 | CH13: 3.7 | CI13: 3.8 | CJ13: 1.94 | CK13: 3.96 | CL13: 3.81 | CM13: 2.15 | CN13: 3.96 | CO13: 3.93 | CP13: 1.98 | CQ13: 3.78 | CR13: 3.72 | CS13: 2 | CT13: 3.95 | CU13: 4 | CV13: 1.62 | CW13: 2.3 | CX13: 1.67 | CY13: 2.32 | CZ13: 1.76 | DA13: 2.35 | DB13: 1.67 | DC13: 2.25 | DD13: 1.71 | DE13: 2.38 | DF13: -0.5 | DG13: 1.98 | DH13: 1.95 | DI13: 1.98 | DJ13: 1.94 | DK13: 2.13 | DL13: 1.98 | DM13: 1.99 | DN13: 1.88 | DO13: 2 | DP13: 1.99
A14: E0 | B14: 24/08/2024 | C14: 0.625 | D14: Fulham | E14: Leicester | F14: 2 | G14: 1 | H14: H | I14: 1 | J14: 1 | K14: D | L14: D Bond | M14: 18 | N14: 10 | O14: 6 | P14: 4 | Q14: 14 | R14: 13 | S14: 7 | T14: 5 | U14: 2 | V14: 2 | W14: 0 | X14: 0 | Y14: 1.8 | Z14: 3.75 | AA14: 4.2 | AB14: 1.8 | AC14: 3.75 | AD14: 4.33 | AE14: 1.83 | AF14: 3.7 | AG14: 4.5 | AH14: 1.84 | AI14: 3.67 | AJ14: 4.56 | AK14: 1.83 | AL14: 3.7 | AM14: 4.33 | AN14: 1.86 | AO14: 3.89 | AP14: 4.32 | AQ14: 1.9 | AR14: 3.89 | AS14: 4.7 | AT14: 1.83 | AU14: 3.73 | AV14: 4.38 | AW14: 1.89 | AX14: 3.85 | AY14: 4.6 | AZ14: 1.89 | BA14: 2.01 | BB14: 1.9 | BC14: 1.99 | BD14: 1.91 | BE14: 2.06 | BF14: 1.87 | BG14: 1.97 | BH14: 1.96 | BI14: 2 | BJ14: -0.75 | BK14: 2.03 | BL14: 1.78 | BM14: 2.1 | BN14: 1.81 | BO14: 2.12 | BP14: 1.84 | BQ14: 2.06 | BR14: 1.8 | BS14: 2.14 | BT14: 1.85 | BU14: 1.85 | BV14: 3.75 | BW14: 4.1 | BX14: 1.9 | BY14: 3.6 | BZ14: 4 | CA14: 1.9 | CB14: 3.6 | CC14: 4.2 | CD14: 1.88 | CE14: 3.81 | CF14: 4.26 | CG14: 1.91 | CH14: 3.6 | CI14: 4.2 | CJ14: 1.89 | CK14: 3.82 | CL14: 4.18 | CM14: 1.91 | CN14: 3.9 | CO14: 4.7 | CP14: 1.88 | CQ14: 3.71 | CR14: 4.21 | CS14: 1.93 | CT14: 3.8 | CU14: 4.5 | CV14: 1.86 | CW14: 2.04 | CX14: 1.87 | CY14: 2.04 | CZ14: 1.95 | DA14: 2.1 | DB14: 1.87 | DC14: 1.98 | DD14: 1.92 | DE14: 2.08 | DF14: -0.5 | DG14: 1.88 | DH14: 2.05 | DI14: 1.88 | DJ14: 2.04 | DK14: 1.91 | DL14: 2.06 | DM14: 1.87 | DN14: 2 | DO14: 1.93 | DP14: 2.06
A15: E0 | B15: 24/08/2024 | C15: 0.625 | D15: Man City | E15: Ipswich | F15: 4 | G15: 1 | H15: H | I15: 3 | J15: 1 | K15: H | L15: M Salisbury | M15: 14 | N15: 1 | O15: 5 | P15: 1 | Q15: 4 | R15: 15 | S15: 10 | T15: 1 | U15: 2 | V15: 3 | W15: 0 | X15: 0 | Y15: 1.08 | Z15: 12 | AA15: 21 | AB15: 1.1 | AC15: 12.5 | AD15: 23 | AE15: 1.08 | AF15: 13 | AG15: 31 | AH15: 1.08 | AI15: 13.21 | AJ15: 25.71 | AK15: 1.1 | AL15: 11 | AM15: 26 | AN15: 1.1 | AO15: 12.2 | AP15: 27 | AQ15: 1.1 | AR15: 14 | AS15: 34 | AT15: 1.09 | AU15: 12.17 | AV15: 26.97 | AW15: 1.1 | AX15: 15 | AY15: 34 | AZ15: 1.3 | BA15: 3.5 | BB15: 1.29 | BC15: 3.36 | BD15: 1.3 | BE15: 3.8 | BF15: 1.29 | BG15: 3.54 | BJ15: -2.75 | BK15: 2.04 | BL15: 1.86 | BM15: 2.05 | BN15: 1.85 | BO15: 2.07 | BP15: 1.91 | BQ15: 2.01 | BR15: 1.85 | BS15: 2.07 | BT15: 1.87 | BU15: 1.1 | BV15: 10 | BW15: 23 | BX15: 1.11 | BY15: 11.5 | BZ15: 21 | CA15: 1.1 | CB15: 11 | CC15: 26 | CD15: 1.1 | CE15: 11 | CF15: 31 | CG15: 1.1 | CH15: 10 | CI15: 29 | CJ15: 1.09 | CK15: 11 | CL15: 26 | CM15: 1.12 | CN15: 15 | CO15: 32 | CP15: 1.09 | CQ15: 11.44 | CR15: 27.5 | CS15: 1.12 | CT15: 12.5 | CU15: 32 | CV15: 1.3 | CW15: 3.5 | CX15: 1.29 | CY15: 3.36 | CZ15: 1.32 | DA15: 3.75 | DB15: 1.29 | DC15: 3.62 | DD15: 1.33 | DE15: 4 | DF15: -2.5 | DG15: 1.9 | DH15: 2.03 | DI15: 1.82 | DJ15: 2.07 | DK15: 1.93 | DL15: 2.13 | DM15: 1.84 | DN15: 2.04 | DO15: 1.89 | DP15: 2.09
A16: E0 | B16: 24/08/2024 | C16: 0.625 | D16: Southampton | E16: Nott'm Forest | F16: 0 | G16: 1 | H16: A | I16: 0 | J16: 0 | K16: D | L16: S Barrott | M16: 5 | N16: 23 | O16: 1 | P16: 8 | Q16: 14 | R16: 14 | S16: 4 | T16: 10 | U16: 3 | V16: 3 | W16: 0 | X16: 0 | Y16: 2.55 | Z16: 3.3 | AA16: 2.8 | AB16: 2.5 | AC16: 3.4 | AD16: 2.8 | AE16: 2.55 | AF16: 3.4 | AG16: 2.8 | AH16: 2.59 | AI16: 3.28 | AJ16: 2.92 | AK16: 2.5 | AL16: 3.4 | AM16: 2.88 | AN16: 2.59 | AO16: 3.42 | AP16: 2.88 | AQ16: 2.66 | AR16: 3.42 | AS16: 2.92 | AT16: 2.57 | AU16: 3.32 | AV16: 2.84 | AW16: 2.62 | AX16: 3.5 | AY16: 2.96 | AZ16: 2.01 | BA16: 1.89 | BB16: 2.01 | BC16: 1.88 | BD16: 2.02 | BE16: 1.93 | BF16: 1.97 | BG16: 1.87 | BH16: 2.06 | BI16: 1.89 | BJ16: 0 | BK16: 1.83 | BL16: 2.07 | BM16: 1.84 | BN16: 2.08 | BO16: 1.85 | BP16: 2.09 | BQ16: 1.83 | BR16: 2.05 | BS16: 1.9 | BT16: 2.07 | BU16: 2.3 | BV16: 3.5 | BW16: 3 | BX16: 2.3 | BY16: 3.5 | BZ16: 3.1 | CA16: 2.3 | CB16: 3.4 | CC16: 3.1 | CD16: 2.33 | CE16: 3.54 | CF16: 3.11 | CG16: 2.3 | CH16: 3.4 | CI16: 3.2 | CJ16: 2.42 | CK16: 3.58 | CL16: 2.97 | CM16: 2.58 | CN16: 3.59 | CO16: 3.2 | CP16: 2.36 | CQ16: 3.48 | CR16: 3.04 | CS16: 2.42 | CT16: 3.6 | CU16: 3.2 | CV16: 1.8 | CW16: 2 | CX16: 1.85 | CY16: 2.07 | CZ16: 1.97 | DA16: 2.18 | DB16: 1.83 | DC16: 2.03 | DD16: 1.85 | DE16: 2.16 | DF16: -0.25 | DG16: 2.03 | DH16: 1.9 | DI16: 2.03 | DJ16: 1.88 | DK16: 2.19 | DL16: 1.91 | DM16: 2.03 | DN16: 1.84 | DO16: 2.08 | DP16: 1.91
A17: E0 | B17: 24/08/2024 | C17: 0.625 | D17: Tottenham | E17: Everton | F17: 4 | G17: 0 | H17: H | I17: 2 | J17: 0 | K17: H | L17: A Taylor | M17: 13 | N17: 10 | O17: 7 | P17: 1 | Q17: 11 | R17: 15 | S17: 12 | T17: 5 | U17: 0 | V17: 0 | W17: 0 | X17: 0 | Y17: 1.44 | Z17: 4.75 | AA17: 6.5 | AB17: 1.43 | AC17: 5 | AD17: 6.75 | AE17: 1.4 | AF17: 5 | AG17: 7 | AH17: 1.45 | AI17: 4.87 | AJ17: 7.03 | AK17: 1.44 | AL17: 4.8 | AM17: 7 | AN17: 1.47 | AO17: 5.08 | AP17: 6.81 | AQ17: 1.49 | AR17: 5.1 | AS17: 7.3 | AT17: 1.44 | AU17: 4.95 | AV17: 6.75 | AW17: 1.45 | AX17: 5.3 | AY17: 7.8 | AZ17: 1.5 | BA17: 2.63 | BB17: 1.54 | BC17: 2.59 | BD17: 1.54 | BE17: 2.63 | BF17: 1.51 | BG17: 2.55 | BH17: 1.56 | BI17: 2.72 | BJ17: -1.25 | BK17: 1.95 | BL17: 1.95 | BM17: 1.98 | BN17: 1.93 | BO17: 1.98 | BP17: 1.98 | BQ17: 1.94 | BR17: 1.91 | BS17: 1.95 | BT17: 1.99 | BU17: 1.36 | BV17: 5.25 | BW17: 7.5 | BX17: 1.37 | BY17: 5.25 | BZ17: 7.75 | CA17: 1.33 | CB17: 5.5 | CC17: 8 | CD17: 1.37 | CE17: 5.66 | CF17: 8 | CG17: 1.35 | CH17: 5.5 | CI17: 8.5 | CJ17: 1.39 | CK17: 5.38 | CL17: 7.97 | CM17: 1.41 | CN17: 5.73 | CO17: 8.5 | CP17: 1.37 | CQ17: 5.39 | CR17: 7.91 | CS17: 1.37 | CT17: 6 | CU17: 9.2 | CV17: 1.4 | CW17: 3 | CX17: 1.43 | CY17: 2.95 | CZ17: 1.5 | DA17: 3.12 | DB17: 1.42 | DC17: 2.89 | DD17: 1.48 | DE17: 3.05 | DF17: -1.5 | DG17: 1.99 | DH17: 1.94 | DI17: 2.01 | DJ17: 1.92 | DK17: 2.11 | DL17: 1.97 | DM17: 2 | DN17: 1.88 | DO17: 2 | DP17: 1.96
A18: E0 | B18: 24/08/2024 | C18: 0.72916667 | D18: Aston Villa | E18: Arsenal | F18: 0 | G18: 2 | H18: A | I18: 0 | J18: 0 | K18: D | L18: M Oliver | M18: 11 | N18: 9 | O18: 3 | P18: 4 | Q18: 8 | R18: 15 | S18: 4 | T18: 1 | U18: 1 | V18: 3 | W18: 0 | X18: 0 | Y18: 4.33 | Z18: 3.8 | AA18: 1.75 | AB18: 4.2 | AC18: 3.9 | AD18: 1.8 | AE18: 4.5 | AF18: 3.9 | AG18: 1.75 | AH18: 4.55 | AI18: 3.98 | AJ18: 1.77 | AK18: 4.33 | AL18: 3.9 | AM18: 1.8 | AN18: 4.32 | AO18: 4 | AP18: 1.84 | AQ18: 4.7 | AR18: 4.1 | AS18: 1.84 | AT18: 4.41 | AU18: 3.92 | AV18: 1.78 | AW18: 4.7 | AX18: 4.1 | AY18: 1.8 | AZ18: 1.73 | BA18: 2.1 | BB18: 1.75 | BC18: 2.15 | BD18: 1.78 | BE18: 2.23 | BF18: 1.73 | BG18: 2.13 | BJ18: 0.75 | BK18: 1.9 | BL18: 2 | BM18: 1.9 | BN18: 2 | BO18: 1.91 | BP18: 2.02 | BQ18: 1.86 | BR18: 1.98 | BS18: 1.95 | BT18: 2.02 | BU18: 4.5 | BV18: 4 | BW18: 1.73 | BX18: 4.5 | BY18: 3.9 | BZ18: 1.75 | CA18: 4.75 | CB18: 3.9 | CC18: 1.73 | CD18: 4.85 | CE18: 4.04 | CF18: 1.74 | CG18: 4.8 | CH18: 4 | CI18: 1.7 | CJ18: 4.8 | CK18: 4.08 | CL18: 1.73 | CM18: 4.85 | CN18: 4.16 | CO18: 1.78 | CP18: 4.66 | CQ18: 4.02 | CR18: 1.74 | CS18: 5 | CT18: 4.1 | CU18: 1.78 | CV18: 1.73 | CW18: 2.1 | CX18: 1.76 | CY18: 2.15 | CZ18: 1.76 | DA18: 2.27 | DB18: 1.72 | DC18: 2.18 | DD18: 1.87 | DE18: 2.12 | DF18: 0.75 | DG18: 1.96 | DH18: 1.97 | DI18: 1.98 | DJ18: 1.94 | DK18: 2 | DL18: 1.99 | DM18: 1.94 | DN18: 1.92 | DO18: 1.97 | DP18: 2
A19: E0 | B19: 25/08/2024 | C19: 0.58333333 | D19: Bournemouth | E19: Newcastle | F19: 1 | G19: 1 | H19: D | I19: 1 | J19: 0 | K19: H | L19: D Coote | M19: 16 | N19: 14 | O19: 4 | P19: 5 | Q19: 19 | R19: 8 | S19: 8 | T19: 9 | U19: 2 | V19: 2 | W19: 0 | X19: 0 | Y19: 2.9 | Z19: 3.8 | AA19: 2.2 | AB19: 3 | AC19: 3.9 | AD19: 2.2 | AE19: 3 | AF19: 3.8 | AG19: 2.2 | AH19: 3.05 | AI19: 3.73 | AJ19: 2.28 | AK19: 3 | AL19: 3.8 | AM19: 2.25 | AN19: 3.05 | AO19: 3.95 | AP19: 2.25 | AQ19: 3.06 | AR19: 3.95 | AS19: 2.32 | AT19: 2.99 | AU19: 3.8 | AV19: 2.25 | AW19: 3.15 | AX19: 3.95 | AY19: 2.3 | AZ19: 1.57 | BA19: 2.38 | BB19: 1.61 | BC19: 2.43 | BD19: 1.61 | BE19: 2.5 | BF19: 1.56 | BG19: 2.44 | BH19: 1.62 | BI19: 2.56 | BJ19: 0.25 | BK19: 1.92 | BL19: 1.98 | BM19: 1.91 | BN19: 2 | BO19: 1.95 | BP19: 2 | BQ19: 1.9 | BR19: 1.94 | BS19: 1.96 | BT19: 2.01 | BU19: 2.55 | BV19: 3.6 | BW19: 2.6 | BX19: 2.5 | BY19: 3.7 | BZ19: 2.65 | CA19: 2.5 | CB19: 3.6 | CC19: 2.7 | CD19: 2.63 | CE19: 3.66 | CF19: 2.68 | CG19: 2.6 | CH19: 3.6 | CI19: 2.62 | CJ19: 2.68 | CK19: 3.7 | CL19: 2.58 | CM19: 2.68 | CN19: 3.75 | CO19: 2.74 | CP19: 2.57 | CQ19: 3.65 | CR19: 2.64 | CS19: 2.66 | CT19: 3.75 | CU19: 2.78 | CV19: 1.57 | CW19: 2.38 | CX19: 1.58 | CY19: 2.49 | CZ19: 1.66 | DA19: 2.55 | DB19: 1.57 | DC19: 2.44 | DD19: 1.62 | DE19: 2.58 | DF19: 0 | DG19: 1.93 | DH19: 2 | DI19: 1.94 | DJ19: 1.98 | DK19: 1.94 | DL19: 2.04 | DM19: 1.92 | DN19: 1.97 | DO19: 1.96 | DP19: 2.03
A20: E0 | B20: 25/08/2024 | C20: 0.58333333 | D20: Wolves | E20: Chelsea | F20: 2 | G20: 6 | H20: A | I20: 2 | J20: 2 | K20: D | L20: D England | M20: 12 | N20: 14 | O20: 4 | P20: 8 | Q20: 13 | R20: 13 | S20: 5 | T20: 5 | U20: 2 | V20: 3 | W20: 0 | X20: 0 | Y20: 4.33 | Z20: 4 | AA20: 1.75 | AB20: 4.4 | AC20: 4 | AD20: 1.75 | AE20: 4.5 | AF20: 4 | AG20: 1.75 | AH20: 4.46 | AI20: 4.03 | AJ20: 1.78 | AK20: 4.4 | AL20: 4 | AM20: 1.75 | AN20: 4.27 | AO20: 4.17 | AP20: 1.81 | AQ20: 4.6 | AR20: 4.17 | AS20: 1.82 | AT20: 4.37 | AU20: 4 | AV20: 1.77 | AW20: 4.7 | AX20: 4.2 | AY20: 1.81 | AZ20: 1.62 | BA20: 2.3 | BB20: 1.65 | BC20: 2.33 | BD20: 1.68 | BE20: 2.34 | BF20: 1.64 | BG20: 2.29 | BH20: 1.69 | BI20: 2.38 | BJ20: 0.75 | BK20: 1.89 | BL20: 2.01 | BM20: 1.9 | BN20: 2.01 | BO20: 1.91 | BP20: 2.02 | BQ20: 1.87 | BR20: 1.98 | BS20: 1.94 | BT20: 2.02 | BU20: 3.75 | BV20: 3.8 | BW20: 1.9 | BX20: 3.75 | BY20: 3.8 | BZ20: 1.9 | CA20: 3.9 | CB20: 3.9 | CC20: 1.91 | CD20: 3.91 | CE20: 3.94 | CF20: 1.93 | CG20: 3.9 | CH20: 3.8 | CI20: 1.91 | CJ20: 4.02 | CK20: 3.89 | CL20: 1.9 | CM20: 4.1 | CN20: 3.99 | CO20: 1.93 | CP20: 3.89 | CQ20: 3.89 | CR20: 1.91 | CS20: 4 | CT20: 4 | CU20: 1.96 | CV20: 1.57 | CW20: 2.38 | CX20: 1.62 | CY20: 2.41 | CZ20: 1.69 | DA20: 2.47 | DB20: 1.61 | DC20: 2.36 | DD20: 1.64 | DE20: 2.54 | DF20: 0.5 | DG20: 1.99 | DH20: 1.94 | DI20: 1.99 | DJ20: 1.93 | DK20: 2.02 | DL20: 1.94 | DM20: 1.97 | DN20: 1.9 | DO20: 2.03 | DP20: 1.96
A21: E0 | B21: 25/08/2024 | C21: 0.6875 | D21: Liverpool | E21: Brentford | F21: 2 | G21: 0 | H21: H | I21: 1 | J21: 0 | K21: H | L21: S Attwell | M21: 19 | N21: 8 | O21: 8 | P21: 2 | Q21: 10 | R21: 7 | S21: 9 | T21: 4 | U21: 2 | V21: 3 | W21: 0 | X21: 0 | Y21: 1.27 | Z21: 5.75 | AA21: 11 | AB21: 1.25 | AC21: 6.75 | AD21: 10.5 | AE21: 1.22 | AF21: 7 | AG21: 11 | AH21: 1.25 | AI21: 7.05 | AJ21: 10.11 | AK21: 1.25 | AL21: 6.5 | AM21: 11 | AN21: 1.28 | AO21: 6.6 | AP21: 10.6 | AQ21: 1.28 | AR21: 7.5 | AS21: 11.5 | AT21: 1.25 | AU21: 6.78 | AV21: 10.37 | AW21: 1.26 | AX21: 7.6 | AY21: 12.5 | AZ21: 1.36 | BA21: 3.2 | BB21: 1.36 | BC21: 3.23 | BD21: 1.4 | BE21: 3.4 | BF21: 1.35 | BG21: 3.2 | BJ21: -1.75 | BK21: 1.89 | BL21: 2.01 | BM21: 1.89 | BN21: 1.99 | BO21: 1.89 | BP21: 2.05 | BQ21: 1.85 | BR21: 2 | BS21: 1.88 | BT21: 2.01 | BU21: 1.2 | BV21: 7 | BW21: 13 | BX21: 1.24 | BY21: 7 | BZ21: 11 | CA21: 1.18 | CB21: 7 | CC21: 12 | CD21: 1.22 | CE21: 7.75 | CF21: 12.5 | CG21: 1.22 | CH21: 6.5 | CI21: 13 | CJ21: 1.22 | CK21: 7.28 | CL21: 13.5 | CM21: 1.25 | CN21: 7.75 | CO21: 13.5 | CP21: 1.22 | CQ21: 7.19 | CR21: 11.82 | CS21: 1.23 | CT21: 8 | CU21: 14.5 | CV21: 1.3 | CW21: 3.5 | CX21: 1.33 | CY21: 3.46 | CZ21: 1.34 | DA21: 3.55 | DB21: 1.32 | DC21: 3.42 | DD21: 1.35 | DE21: 3.75 | DF21: -2 | DG21: 2.06 | DH21: 1.87 | DI21: 2.07 | DJ21: 1.85 | DK21: 2.07 | DL21: 1.91 | DM21: 2.03 | DN21: 1.85 | DO21: 2.08 | DP21: 1.92
A22: E0 | B22: 31/08/2024 | C22: 0.52083333 | D22: Arsenal | E22: Brighton | F22: 1 | G22: 1 | H22: D | I22: 1 | J22: 0 | K22: H | L22: C Kavanagh | M22: 11 | N22: 22 | O22: 7 | P22: 4 | Q22: 12 | R22: 7 | S22: 3 | T22: 7 | U22: 3 | V22: 2 | W22: 1 | X22: 0 | Y22: 1.33 | Z22: 5.5 | AA22: 8.5 | AB22: 1.36 | AC22: 5.5 | AD22: 8 | AE22: 1.33 | AF22: 5.5 | AG22: 8.5 | AH22: 1.34 | AI22: 5.87 | AJ22: 8.1 | AK22: 1.33 | AL22: 5.5 | AM22: 8.5 | AN22: 1.37 | AO22: 5.84 | AP22: 7.9 | AQ22: 1.37 | AR22: 6 | AS22: 9 | AT22: 1.35 | AU22: 5.66 | AV22: 8.11 | AW22: 1.36 | AX22: 6 | AY22: 9.4 | AZ22: 1.53 | BA22: 2.5 | BB22: 1.54 | BC22: 2.59 | BD22: 1.57 | BE22: 2.59 | BF22: 1.53 | BG22: 2.52 | BH22: 1.58 | BI22: 2.66 | BJ22: -1.5 | BK22: 2.01 | BL22: 1.89 | BM22: 2.02 | BN22: 1.89 | BO22: 2.05 | BP22: 1.92 | BQ22: 2 | BR22: 1.86 | BS22: 2.03 | BT22: 1.92 | BU22: 1.36 | BV22: 5.25 | BW22: 7.5 | BX22: 1.37 | BY22: 5.5 | BZ22: 7.5 | CA22: 1.33 | CB22: 5 | CC22: 8.5 | CD22: 1.37 | CE22: 5.48 | CF22: 8.43 | CG22: 1.36 | CH22: 5 | CI22: 8.5 | CJ22: 1.39 | CK22: 5.38 | CL22: 7.97 | CM22: 1.4 | CN22: 5.6 | CO22: 8.6 | CP22: 1.37 | CQ22: 5.37 | CR22: 8 | CS22: 1.4 | CT22: 5.7 | CU22: 8.8 | CV22: 1.53 | CW22: 2.5 | CX22: 1.56 | CY22: 2.56 | CZ22: 1.58 | DA22: 2.63 | DB22: 1.54 | DC22: 2.52 | DD22: 1.58 | DE22: 2.72 | DF22: -1.5 | DG22: 2.08 | DH22: 1.85 | DI22: 2.09 | DJ22: 1.85 | DK22: 2.12 | DL22: 1.86 | DM22: 2.05 | DN22: 1.83 | DO22: 2.14 | DP22: 1.86
A23: E0 | B23: 31/08/2024 | C23: 0.625 | D23: Brentford | E23: Southampton | F23: 3 | G23: 1 | H23: H | I23: 1 | J23: 0 | K23: H | L23: J Smith | M23: 20 | N23: 18 | O23: 7 | P23: 6 | Q23: 10 | R23: 7 | S23: 2 | T23: 8 | U23: 2 | V23: 1 | W23: 0 | X23: 0 | Y23: 1.75 | Z23: 3.9 | AA23: 4.33 | AB23: 1.75 | AC23: 3.9 | AD23: 4.4 | AE23: 1.75 | AF23: 3.9 | AG23: 4.6 | AH23: 1.79 | AI23: 3.9 | AJ23: 4.51 | AK23: 1.75 | AL23: 3.9 | AM23: 4.6 | AN23: 1.79 | AO23: 4.12 | AP23: 4.47 | AQ23: 1.82 | AR23: 4.12 | AS23: 4.7 | AT23: 1.77 | AU23: 3.97 | AV23: 4.46 | AW23: 1.82 | AX23: 4.1 | AY23: 4.8 | AZ23: 1.73 | BA23: 2.1 | BB23: 1.74 | BC23: 2.18 | BD23: 1.76 | BE23: 2.21 | BF23: 1.73 | BG23: 2.15 | BH23: 1.79 | BI23: 2.24 | BJ23: -0.75 | BK23: 2.01 | BL23: 1.89 | BM23: 2 | BN23: 1.9 | BO23: 2.04 | BP23: 1.92 | BQ23: 1.97 | BR23: 1.89 | BS23: 2.03 | BT23: 1.93 | BU23: 1.8 | BV23: 3.9 | BW23: 4.33 | BX23: 1.8 | BY23: 3.8 | BZ23: 4.33 | CA23: 1.8 | CB23: 3.8 | CC23: 4.5 | CD23: 1.82 | CE23: 3.91 | CF23: 4.46 | CG23: 1.8 | CH23: 3.75 | CI23: 4.5 | CJ23: 1.79 | CK23: 3.94 | CL23: 4.59 | CM23: 1.83 | CN23: 3.95 | CO23: 4.59 | CP23: 1.8 | CQ23: 3.86 | CR23: 4.42 | CS23: 1.86 | CT23: 4 | CU23: 4.6 | CV23: 1.8 | CW23: 2 | CX23: 1.82 | CY23: 2.07 | CZ23: 1.85 | DA23: 2.12 | DB23: 1.8 | DC23: 2.05 | DD23: 1.84 | DE23: 2.16 | DF23: -0.75 | DG23: 2.08 | DH23: 1.85 | DI23: 2.09 | DJ23: 1.84 | DK23: 2.09 | DL23: 1.9 | DM23: 2.02 | DN23: 1.85 | DO23: 2.11 | DP23: 1.87
A24: E0 | B24: 31/08/2024 | C24: 0.625 | D24: Everton | E24: Bournemouth | F24: 2 | G24: 3 | H24: A | I24: 0 | J24: 0 | K24: D | L24: S Attwell | M24: 18 | N24: 17 | O24: 8 | P24: 7 | Q24: 6 | R24: 1 | S24: 8 | T24: 4 | U24: 2 | V24: 1 | W24: 0 | X24: 0 | Y24: 2.75 | Z24: 3.4 | AA24: 2.55 | AB24: 2.65 | AC24: 3.4 | AD24: 2.6 | AE24: 2.75 | AF24: 3.4 | AG24: 2.6 | AH24: 2.82 | AI24: 3.38 | AJ24: 2.62 | AK24: 2.75 | AL24: 3.4 | AM24: 2.6 | AN24: 2.83 | AO24: 3.48 | AP24: 2.6 | AQ24: 2.85 | AR24: 3.5 | AS24: 2.64 | AT24: 2.78 | AU24: 3.4 | AV24: 2.59 | AW24: 2.86 | AX24: 3.55 | AY24: 2.68 | AZ24: 1.92 | BA24: 1.98 | BB24: 1.93 | BC24: 1.96 | BD24: 1.93 | BE24: 2 | BF24: 1.87 | BG24: 1.95 | BH24: 1.96 | BI24: 2 | BJ24: 0 | BK24: 2.01 | BL24: 1.89 | BM24: 2.03 | BN24: 1.88 | BO24: 2.03 | BP24: 1.9 | BQ24: 2 | BR24: 1.87 | BS24: 2.05 | BT24: 1.93 | BU24: 3 | BV24: 3.4 | BW24: 2.35 | BX24: 2.85 | BY24: 3.4 | BZ24: 2.45 | CA24: 2.88 | CB24: 3.4 | CC24: 2.45 | CD24: 3.14 | CE24: 3.45 | CF24: 2.39 | CG24: 2.9 | CH24: 3.4 | CI24: 2.45 | CJ24: 2.96 | CK24: 3.48 | CL24: 2.47 | CM24: 3.14 | CN24: 3.55 | CO24: 2.52 | CP24: 2.96 | CQ24: 3.45 | CR24: 2.43 | CS24: 3.1 | CT24: 3.55 | CU24: 2.48 | CV24: 1.87 | CW24: 2.03 | CX24: 1.88 | CY24: 2.03 | CZ24: 1.9 | DA24: 2.06 | DB24: 1.84 | DC24: 2 | DD24: 1.9 | DE24: 2.08 | DF24: 0.25 | DG24: 1.85 | DH24: 2.08 | DI24: 1.87 | DJ24: 2.06 | DK24: 1.87 | DL24: 2.14 | DM24: 1.81 | DN24: 2.06 | DO24: 1.86 | DP24: 2.14
A25: E0 | B25: 31/08/2024 | C25: 0.625 | D25: Ipswich | E25: Fulham | F25: 1 | G25: 1 | H25: D | I25: 1 | J25: 1 | K25: D | L25: L Smith | M25: 11 | N25: 9 | O25: 4 | P25: 4 | Q25: 15 | R25: 15 | S25: 8 | T25: 6 | U25: 2 | V25: 3 | W25: 0 | X25: 0 | Y25: 3 | Z25: 3.5 | AA25: 2.3 | AB25: 3.1 | AC25: 3.5 | AD25: 2.25 | AE25: 3.1 | AF25: 3.4 | AG25: 2.3 | AH25: 3.14 | AI25: 3.53 | AJ25: 2.32 | AK25: 3.1 | AL25: 3.5 | AM25: 2.3 | AN25: 3.13 | AO25: 3.66 | AP25: 2.31 | AQ25: 3.2 | AR25: 3.66 | AS25: 2.38 | AT25: 3.1 | AU25: 3.5 | AV25: 2.31 | AW25: 3.2 | AX25: 3.6 | AY25: 2.42 | AZ25: 1.84 | BA25: 2.06 | BB25: 1.83 | BC25: 2.06 | BD25: 1.88 | BE25: 2.07 | BF25: 1.82 | BG25: 2.03 | BH25: 1.83 | BI25: 2.12 | BJ25: 0.25 | BK25: 1.87 | BL25: 2.03 | BM25: 1.89 | BN25: 2.01 | BO25: 1.91 | BP25: 2.08 | BQ25: 1.86 | BR25: 1.98 | BS25: 1.91 | BT25: 2.08 | BU25: 3 | BV25: 3.4 | BW25: 2.38 | BX25: 2.95 | BY25: 3.4 | BZ25: 2.4 | CA25: 3 | CB25: 3.4 | CC25: 2.38 | CD25: 3.07 | CE25: 3.43 | CF25: 2.43 | CG25: 3 | CH25: 3.4 | CI25: 2.38 | CJ25: 3.2 | CK25: 3.46 | CL25: 2.33 | CM25: 3.2 | CN25: 3.5 | CO25: 2.45 | CP25: 3.03 | CQ25: 3.41 | CR25: 2.4 | CS25: 3.15 | CT25: 3.55 | CU25: 2.46 | CV25: 1.95 | CW25: 1.95 | CX25: 1.93 | CY25: 1.97 | CZ25: 1.96 | DA25: 2 | DB25: 1.9 | DC25: 1.94 | DD25: 2 | DE25: 1.98 | DF25: 0.25 | DG25: 1.82 | DH25: 2.11 | DI25: 1.83 | DJ25: 2.11 | DK25: 1.86 | DL25: 2.11 | DM25: 1.81 | DN25: 2.06 | DO25: 1.88 | DP25: 2.11
A26: E0 | B26: 31/08/2024 | C26: 0.625 | D26: Leicester | E26: Aston Villa | F26: 1 | G26: 2 | H26: A | I26: 0 | J26: 1 | K26: A | L26: D Coote | M26: 9 | N26: 10 | O26: 3 | P26: 5 | Q26: 13 | R26: 21 | S26: 1 | T26: 4 | U26: 4 | V26: 5 | W26: 0 | X26: 0 | Y26: 4.5 | Z26: 4 | AA26: 1.7 | AB26: 4.4 | AC26: 3.9 | AD26: 1.77 | AE26: 4.6 | AF26: 3.9 | AG26: 1.75 | AH26: 4.8 | AI26: 4.09 | AJ26: 1.71 | AK26: 4.6 | AL26: 3.9 | AM26: 1.75 | AN26: 4.53 | AO26: 4.17 | AP26: 1.77 | AQ26: 4.9 | AR26: 4.2 | AS26: 1.78 | AT26: 4.62 | AU26: 4.02 | AV26: 1.74 | AW26: 4.9 | AX26: 4.1 | AY26: 1.8 | AZ26: 1.67 | BA26: 2.2 | BB26: 1.68 | BC26: 2.27 | BD26: 1.76 | BE26: 2.3 | BF26: 1.69 | BG26: 2.21 | BH26: 1.73 | BI26: 2.28 | BJ26: 0.75 | BK26: 1.95 | BL26: 1.95 | BM26: 1.98 | BN26: 1.93 | BO26: 1.98 | BP26: 1.99 | BQ26: 1.93 | BR26: 1.91 | BS26: 1.98 | BT26: 1.98 | BU26: 4 | BV26: 3.7 | BW26: 1.85 | BX26: 3.8 | BY26: 3.7 | BZ26: 1.95 | CA26: 3.9 | CB26: 3.75 | CC26: 1.95 | CD26: 4.01 | CE26: 3.87 | CF26: 1.92 | CG26: 4 | CH26: 3.7 | CI26: 1.91 | CJ26: 4.2 | CK26: 3.7 | CL26: 1.91 | CM26: 4.2 | CN26: 3.88 | CO26: 1.95 | CP26: 4 | CQ26: 3.76 | CR26: 1.91 | CS26: 4.1 | CT26: 3.95 | CU26: 1.96 | CV26: 1.73 | CW26: 2.1 | CX26: 1.8 | CY26: 2.1 | CZ26: 1.82 | DA26: 2.14 | DB26: 1.78 | DC26: 2.08 | DD26: 1.84 | DE26: 2.18 | DF26: 0.5 | DG26: 1.99 | DH26: 1.94 | DI26: 2 | DJ26: 1.93 | DK26: 2 | DL26: 1.95 | DM26: 1.97 | DN26: 1.9 | DO26: 2.02 | DP26: 1.97
A27: E0 | B27: 31/08/2024 | C27: 0.625 | D27: Nott'm Forest | E27: Wolves | F27: 1 | G27: 1 | H27: D | I27: 1 | J27: 1 | K27: D | L27: S Hooper | M27: 16 | N27: 11 | O27: 5 | P27: 3 | Q27: 15 | R27: 18 | S27: 7 | T27: 3 | U27: 3 | V27: 4 | W27: 0 | X27: 0 | Y27: 2 | Z27: 3.7 | AA27: 3.7 | AB27: 2.1 | AC27: 3.6 | AD27: 3.5 | AE27: 2 | AF27: 3.6 | AG27: 3.75 | AH27: 2.02 | AI27: 3.7 | AJ27: 3.71 | AK27: 2.05 | AL27: 3.6 | AM27: 3.6 | AN27: 2.04 | AO27: 3.76 | AP27: 3.7 | AQ27: 2.1 | AR27: 3.76 | AS27: 3.79 | AT27: 2.03 | AU27: 3.66 | AV27: 3.65 | AW27: 2.08 | AX27: 3.8 | AY27: 3.85 | AZ27: 1.85 | BA27: 2.05 | BB27: 1.85 | BC27: 2.04 | BD27: 1.86 | BE27: 2.09 | BF27: 1.83 | BG27: 2.02 | BH27: 1.88 | BI27: 2.08 | BJ27: -0.5 | BK27: 2.03 | BL27: 1.87 | BM27: 2.03 | BN27: 1.88 | BO27: 2.08 | BP27: 1.88 | BQ27: 2.02 | BR27: 1.85 | BS27: 2.08 | BT27: 1.91 | BU27: 1.95 | BV27: 3.6 | BW27: 3.7 | BX27: 2 | BY27: 3.6 | BZ27: 3.7 | CA27: 2 | CB27: 3.5 | CC27: 3.75 | CD27: 2 | CE27: 3.7 | CF27: 3.88 | CG27: 2 | CH27: 3.5 | CI27: 3.8 | CJ27: 2.05 | CK27: 3.7 | CL27: 3.68 | CM27: 2.05 | CN27: 3.7 | CO27: 3.88 | CP27: 2 | CQ27: 3.61 | CR27: 3.73 | CS27: 2.04 | CT27: 3.75 | CU27: 4 | CV27: 1.91 | CW27: 1.99 | CX27: 1.9 | CY27: 2.01 | CZ27: 1.91 | DA27: 2.01 | DB27: 1.86 | DC27: 1.97 | DD27: 1.94 | DE27: 2.04 | DF27: -0.5 | DG27: 2.01 | DH27: 1.92 | DI27: 2.01 | DJ27: 1.92 | DK27: 2.01 | DL27: 1.94 | DM27: 1.98 | DN27: 1.87 | DO27: 2.06 | DP27: 1.93
A28: E0 | B28: 31/08/2024 | C28: 0.72916667 | D28: West Ham | E28: Man City | F28: 1 | G28: 3 | H28: A | I28: 1 | J28: 2 | K28: A | L28: M Oliver | M28: 10 | N28: 23 | O28: 2 | P28: 8 | Q28: 10 | R28: 3 | S28: 3 | T28: 11 | U28: 3 | V28: 2 | W28: 0 | X28: 0 | Y28: 7 | Z28: 5.5 | AA28: 1.38 | AB28: 7.25 | AC28: 5.25 | AD28: 1.39 | AE28: 7.5 | AF28: 5.5 | AG28: 1.36 | AH28: 7.69 | AI28: 5.64 | AJ28: 1.37 | AK28: 8 | AL28: 5 | AM28: 1.4 | AN28: 7.7 | AO28: 5.44 | AP28: 1.4 | AQ28: 8 | AR28: 5.8 | AS28: 1.41 | AT28: 7.57 | AU28: 5.49 | AV28: 1.38 | AW28: 8.2 | AX28: 5.9 | AY28: 1.4 | AZ28: 1.44 | BA28: 2.75 | BB28: 1.49 | BC28: 2.72 | BD28: 1.5 | BE28: 2.8 | BF28: 1.46 | BG28: 2.73 | BH28: 1.51 | BI28: 2.88 | BJ28: 1.5 | BK28: 1.86 | BL28: 2.04 | BM28: 1.87 | BN28: 2.04 | BO28: 1.89 | BP28: 2.05 | BQ28: 1.85 | BR28: 2.02 | BS28: 1.89 | BT28: 2.05 | BU28: 7.5 | BV28: 5 | BW28: 1.4 | BX28: 6.75 | BY28: 5 | BZ28: 1.42 | CA28: 7.5 | CB28: 5 | CC28: 1.36 | CD28: 7.7 | CE28: 5.25 | CF28: 1.41 | CG28: 7.5 | CH28: 5 | CI28: 1.4 | CJ28: 8.11 | CK28: 5.08 | CL28: 1.41 | CM28: 8.11 | CN28: 5.4 | CO28: 1.46 | CP28: 7.32 | CQ28: 5.14 | CR28: 1.4 | CS28: 8 | CT28: 5.4 | CU28: 1.43 | CV28: 1.53 | CW28: 2.5 | CX28: 1.56 | CY28: 2.57 | CZ28: 1.58 | DA28: 2.73 | DB28: 1.51 | DC28: 2.58 | DD28: 1.6 | DE28: 2.64 | DF28: 1.25 | DG28: 1.98 | DH28: 1.95 | DI28: 1.99 | DJ28: 1.93 | DK28: 2.05 | DL28: 1.95 | DM28: 1.99 | DN28: 1.87 | DO28: 2.03 | DP28: 1.94
A29: E0 | B29: 45300 | C29: 0.5625 | D29: Chelsea | E29: Crystal Palace | F29: 1 | G29: 1 | H29: D | I29: 1 | J29: 0 | K29: H | L29: J Gillett | M29: 13 | N29: 9 | O29: 7 | P29: 3 | Q29: 9 | R29: 13 | S29: 4 | T29: 5 | U29: 4 | V29: 2 | W29: 0 | X29: 0 | Y29: 1.6 | Z29: 4.33 | AA29: 5 | AB29: 1.6 | AC29: 4.4 | AD29: 5 | AE29: 1.6 | AF29: 4.4 | AG29: 5 | AH29: 1.63 | AI29: 4.4 | AJ29: 5.06 | AK29: 1.65 | AL29: 4.33 | AM29: 5 | AN29: 1.66 | AO29: 4.52 | AP29: 4.98 | AQ29: 1.68 | AR29: 4.55 | AS29: 5.2 | AT29: 1.63 | AU29: 4.4 | AV29: 5.01 | AW29: 1.65 | AX29: 4.6 | AY29: 5.4 | AZ29: 1.5 | BA29: 2.63 | BB29: 1.53 | BC29: 2.61 | BD29: 1.55 | BE29: 2.63 | BF29: 1.52 | BG29: 2.56 | BH29: 1.56 | BI29: 2.7 | BJ29: -1 | BK29: 2.04 | BL29: 1.86 | BM29: 2.08 | BN29: 1.84 | BO29: 2.08 | BP29: 1.92 | BQ29: 2.03 | BR29: 1.84 | BS29: 2.03 | BT29: 1.9 | BU29: 1.65 | BV29: 4.33 | BW29: 4.75 | BX29: 1.65 | BY29: 4.2 | BZ29: 4.8 | CA29: 1.62 | CB29: 4 | CC29: 5 | CD29: 1.68 | CE29: 4.24 | CF29: 5.05 | CG29: 1.65 | CH29: 4.2 | CI29: 5 | CJ29: 1.65 | CK29: 4.4 | CL29: 5.08 | CM29: 1.69 | CN29: 4.51 | CO29: 5.1 | CP29: 1.65 | CQ29: 4.3 | CR29: 4.97 | CS29: 1.69 | CT29: 4.3 | CU29: 5.4 | CV29: 1.53 | CW29: 2.5 | CX29: 1.56 | CY29: 2.55 | CZ29: 1.57 | DA29: 2.62 | DB29: 1.54 | DC29: 2.53 | DD29: 1.59 | DE29: 2.66 | DF29: -0.75 | DG29: 1.83 | DH29: 2.1 | DI29: 1.85 | DJ29: 2.08 | DK29: 1.85 | DL29: 2.14 | DM29: 1.8 | DN29: 2.08 | DO29: 1.87 | DP29: 2.13
A30: E0 | B30: 45300 | C30: 0.5625 | D30: Newcastle | E30: Tottenham | F30: 2 | G30: 1 | H30: H | I30: 1 | J30: 0 | K30: H | L30: R Jones | M30: 9 | N30: 20 | O30: 3 | P30: 6 | Q30: 16 | R30: 13 | S30: 7 | T30: 12 | U30: 4 | V30: 4 | W30: 0 | X30: 0 | Y30: 2.5 | Z30: 4 | AA30: 2.5 | AB30: 2.45 | AC30: 4 | AD30: 2.55 | AE30: 2.5 | AF30: 3.9 | AG30: 2.55 | AH30: 2.5 | AI30: 3.96 | AJ30: 2.62 | AK30: 2.5 | AL30: 4 | AM30: 2.5 | AN30: 2.54 | AO30: 4.12 | AP30: 2.56 | AQ30: 2.56 | AR30: 4.12 | AS30: 2.63 | AT30: 2.51 | AU30: 3.97 | AV30: 2.56 | AW30: 2.62 | AX30: 4 | AY30: 2.66 | AZ30: 1.36 | BA30: 3.2 | BB30: 1.41 | BC30: 3.04 | BD30: 1.41 | BE30: 3.22 | BF30: 1.38 | BG30: 3.07 | BH30: 1.42 | BI30: 3.25 | BJ30: 0 | BK30: 1.95 | BL30: 1.95 | BM30: 1.91 | BN30: 2 | BO30: 1.97 | BP30: 2 | BQ30: 1.93 | BR30: 1.94 | BS30: 1.97 | BT30: 2 | BU30: 2.45 | BV30: 3.9 | BW30: 2.55 | BX30: 2.4 | BY30: 3.8 | BZ30: 2.7 | CA30: 2.45 | CB30: 3.75 | CC30: 2.6 | CD30: 2.53 | CE30: 3.89 | CF30: 2.66 | CG30: 2.45 | CH30: 3.9 | CI30: 2.6 | CJ30: 2.6 | CK30: 4 | CL30: 2.53 | CM30: 2.6 | CN30: 4 | CO30: 2.79 | CP30: 2.46 | CQ30: 3.89 | CR30: 2.64 | CS30: 2.58 | CT30: 4 | CU30: 2.72 | CV30: 1.4 | CW30: 3 | CX30: 1.42 | CY30: 3 | CZ30: 1.42 | DA30: 3.14 | DB30: 1.4 | DC30: 3.01 | DD30: 1.43 | DE30: 3.25 | DF30: 0 | DG30: 1.89 | DH30: 2.04 | DI30: 1.92 | DJ30: 2.01 | DK30: 1.92 | DL30: 2.07 | DM30: 1.88 | DN30: 2 | DO30: 1.93 | DP30: 2.05
A31: E0 | B31: 45300 | C31: 0.66666667 | D31: Man United | E31: Liverpool | F31: 0 | G31: 3 | H31: A | I31: 0 | J31: 2 | K31: A | L31: A Taylor | M31: 8 | N31: 11 | O31: 3 | P31: 3 | Q31: 7 | R31: 7 | S31: 5 | T31: 2 | U31: 4 | V31: 1 | W31: 0 | X31: 0 | Y31: 3.7 | Z31: 4.2 | AA31: 1.85 | AB31: 3.7 | AC31: 4.1 | AD31: 1.87 | AE31: 3.9 | AF31: 4.1 | AG31: 1.85 | AH31: 3.93 | AI31: 4.31 | AJ31: 1.82 | AK31: 3.8 | AL31: 4.2 | AM31: 1.85 | AN31: 3.98 | AO31: 4.17 | AP31: 1.87 | AQ31: 4 | AR31: 4.4 | AS31: 1.9 | AT31: 3.82 | AU31: 4.2 | AV31: 1.85 | AW31: 4 | AX31: 4.3 | AY31: 1.9 | AZ31: 1.44 | BA31: 2.75 | BB31: 1.44 | BC31: 2.89 | BD31: 1.45 | BE31: 3.02 | BF31: 1.43 | BG31: 2.84 | BH31: 1.49 | BI31: 3 | BJ31: 0.5 | BK31: 2.04 | BL31: 1.86 | BM31: 2.08 | BN31: 1.82 | BO31: 2.1 | BP31: 1.9 | BQ31: 2.02 | BR31: 1.84 | BS31: 2.08 | BT31: 1.9 | BU31: 3.5 | BV31: 4.1 | BW31: 1.91 | BX31: 3.5 | BY31: 3.9 | BZ31: 1.95 | CA31: 3.5 | CB31: 3.9 | CC31: 1.91 | CD31: 3.51 | CE31: 4.11 | CF31: 2 | CG31: 3.6 | CH31: 3.9 | CI31: 1.95 | CJ31: 3.76 | CK31: 4.19 | CL31: 1.9 | CM31: 3.76 | CN31: 4.19 | CO31: 2 | CP31: 3.56 | CQ31: 4.04 | CR31: 1.95 | CS31: 3.7 | CT31: 4.2 | CU31: 2 | CV31: 1.44 | CW31: 2.75 | CX31: 1.46 | CY31: 2.86 | CZ31: 1.52 | DA31: 2.87 | DB31: 1.45 | DC31: 2.75 | DD31: 1.5 | DE31: 2.98 | DF31: 0.5 | DG31: 1.94 | DH31: 1.99 | DI31: 1.92 | DJ31: 2.01 | DK31: 1.94 | DL31: 2.01 | DM31: 1.91 | DN31: 1.94 | DO31: 1.97 | DP31: 2.02
A32: E0 | B32: 14/09/2024 | C32: 0.52083333 | D32: Southampton | E32: Man United | F32: 0 | G32: 3 | H32: A | I32: 0 | J32: 2 | K32: A | L32: S Attwell | M32: 6 | N32: 20 | O32: 4 | P32: 10 | Q32: 11 | R32: 14 | S32: 0 | T32: 7 | U32: 1 | V32: 4 | W32: 1 | X32: 0 | Y32: 4.5 | Z32: 4 | AA32: 1.7 | AB32: 4.5 | AC32: 4 | AD32: 1.73 | AE32: 4.6 | AF32: 3.9 | AG32: 1.75 | AH32: 4.5 | AI32: 4.13 | AJ32: 1.74 | AK32: 4.75 | AL32: 3.8 | AM32: 1.75 | AN32: 4.83 | AO32: 3.85 | AP32: 1.79 | AQ32: 4.83 | AR32: 4.2 | AS32: 1.79 | AT32: 4.56 | AU32: 4.04 | AV32: 1.74 | AW32: 4.9 | AX32: 4.2 | AY32: 1.78 | AZ32: 1.62 | BA32: 2.3 | BB32: 1.6 | BC32: 2.41 | BD32: 1.67 | BE32: 2.45 | BF32: 1.61 | BG32: 2.36 | BH32: 1.65 | BI32: 2.5 | BJ32: 0.75 | BK32: 1.95 | BL32: 1.95 | BM32: 1.94 | BN32: 1.94 | BO32: 2.02 | BP32: 1.96 | BQ32: 1.93 | BR32: 1.92 | BS32: 1.99 | BT32: 1.97 | BU32: 4 | BV32: 4.1 | BW32: 1.8 | BX32: 4 | BY32: 4 | BZ32: 1.82 | CA32: 4.5 | CB32: 4 | CC32: 1.75 | CD32: 4.2 | CE32: 4.12 | CF32: 1.82 | CG32: 4 | CH32: 4 | CI32: 1.83 | CJ32: 4.33 | CK32: 4.17 | CL32: 1.78 | CM32: 4.5 | CN32: 4.17 | CO32: 1.88 | CP32: 4.19 | CQ32: 4.05 | CR32: 1.8 | CS32: 4.2 | CT32: 4.2 | CU32: 1.88 | CV32: 1.53 | CW32: 2.5 | CX32: 1.56 | CY32: 2.55 | CZ32: 1.6 | DA32: 2.56 | DB32: 1.57 | DC32: 2.46 | DD32: 1.61 | DE32: 2.62 | DF32: 0.75 | DG32: 1.87 | DH32: 2.06 | DI32: 1.88 | DJ32: 2.06 | DK32: 1.91 | DL32: 2.09 | DM32: 1.86 | DN32: 2.01 | DO32: 1.89 | DP32: 2.11
A33: E0 | B33: 14/09/2024 | C33: 0.625 | D33: Brighton | E33: Ipswich | F33: 0 | G33: 0 | H33: D | I33: 0 | J33: 0 | K33: D | L33: S Barrott | M33: 21 | N33: 6 | O33: 6 | P33: 1 | Q33: 14 | R33: 16 | S33: 9 | T33: 2 | U33: 4 | V33: 3 | W33: 0 | X33: 0 | Y33: 1.38 | Z33: 5 | AA33: 7.5 | AB33: 1.38 | AC33: 5.25 | AD33: 7.75 | AE33: 1.36 | AF33: 5 | AG33: 8.5 | AH33: 1.38 | AI33: 5.13 | AJ33: 8.05 | AK33: 1.4 | AL33: 5 | AM33: 8 | AN33: 1.41 | AO33: 5.24 | AP33: 7.8 | AQ33: 1.41 | AR33: 5.4 | AS33: 8.5 | AT33: 1.38 | AU33: 5.16 | AV33: 7.89 | AW33: 1.4 | AX33: 5.6 | AY33: 9 | AZ33: 1.53 | BA33: 2.5 | BB33: 1.56 | BC33: 2.49 | BD33: 1.59 | BE33: 2.52 | BF33: 1.56 | BG33: 2.46 | BH33: 1.59 | BI33: 2.66 | BJ33: -1.5 | BK33: 2.03 | BL33: 1.78 | BM33: 2.09 | BN33: 1.79 | BO33: 2.12 | BP33: 1.83 | BQ33: 2.07 | BR33: 1.8 | BS33: 2.13 | BT33: 1.83 | BU33: 1.45 | BV33: 4.75 | BW33: 6.5 | BX33: 1.5 | BY33: 4.6 | BZ33: 6 | CA33: 1.44 | CB33: 4.5 | CC33: 6.5 | CD33: 1.53 | CE33: 4.61 | CF33: 6.22 | CG33: 1.44 | CH33: 4.75 | CI33: 7 | CJ33: 1.47 | CK33: 4.86 | CL33: 6.92 | CM33: 1.54 | CN33: 4.9 | CO33: 7 | CP33: 1.48 | CQ33: 4.7 | CR33: 6.48 | CS33: 1.51 | CT33: 4.9 | CU33: 7 | CV33: 1.62 | CW33: 2.3 | CX33: 1.68 | CY33: 2.3 | CZ33: 1.68 | DA33: 2.41 | DB33: 1.62 | DC33: 2.34 | DD33: 1.66 | DE33: 2.48 | DF33: -1 | DG33: 1.87 | DH33: 2.06 | DI33: 1.89 | DJ33: 2.04 | DK33: 1.89 | DL33: 2.16 | DM33: 1.8 | DN33: 2.1 | DO33: 1.83 | DP33: 2.19
A34: E0 | B34: 14/09/2024 | C34: 0.625 | D34: Crystal Palace | E34: Leicester | F34: 2 | G34: 2 | H34: D | I34: 0 | J34: 1 | K34: A | L34: T Harrington | M34: 20 | N34: 9 | O34: 4 | P34: 4 | Q34: 11 | R34: 15 | S34: 5 | T34: 2 | U34: 0 | V34: 3 | W34: 0 | X34: 0 | Y34: 1.62 | Z34: 4 | AA34: 5.5 | AB34: 1.62 | AC34: 4.1 | AD34: 5.25 | AE34: 1.62 | AF34: 4 | AG34: 5.5 | AH34: 1.62 | AI34: 4.13 | AJ34: 5.48 | AK34: 1.65 | AL34: 4 | AM34: 5.5 | AN34: 1.66 | AO34: 4.27 | AP34: 5.33 | AQ34: 1.66 | AR34: 4.3 | AS34: 5.6 | AT34: 1.63 | AU34: 4.14 | AV34: 5.38 | AW34: 1.67 | AX34: 4.3 | AY34: 5.9 | AZ34: 1.73 | BA34: 2.1 | BB34: 1.76 | BC34: 2.11 | BD34: 1.8 | BE34: 2.17 | BF34: 1.76 | BG34: 2.1 | BH34: 1.79 | BI34: 2.2 | BJ34: -1 | BK34: 2.08 | BL34: 1.82 | BM34: 2.09 | BN34: 1.81 | BO34: 2.14 | BP34: 1.84 | BQ34: 2.07 | BR34: 1.8 | BS34: 2.13 | BT34: 1.85 | BU34: 1.65 | BV34: 3.9 | BW34: 5.25 | BX34: 1.66 | BY34: 4 | BZ34: 5.25 | CA34: 1.57 | CB34: 4 | CC34: 5.5 | CD34: 1.67 | CE34: 4.02 | CF34: 5.43 | CG34: 1.65 | CH34: 4 | CI34: 5.5 | CJ34: 1.69 | CK34: 3.98 | CL34: 5.36 | CM34: 1.7 | CN34: 4.1 | CO34: 5.5 | CP34: 1.67 | CQ34: 3.98 | CR34: 5.27 | CS34: 1.72 | CT34: 4 | CU34: 5.6 | CV34: 1.88 | CW34: 2.02 | CX34: 1.88 | CY34: 2.03 | CZ34: 1.92 | DA34: 2.05 | DB34: 1.85 | DC34: 2 | DD34: 1.93 | DE34: 2.06 | DF34: -0.75 | DG34: 1.88 | DH34: 2.05 | DI34: 1.87 | DJ34: 2.07 | DK34: 1.92 | DL34: 2.07 | DM34: 1.85 | DN34: 2.02 | DO34: 1.92 | DP34: 2.06
A35: E0 | B35: 14/09/2024 | C35: 0.625 | D35: Fulham | E35: West Ham | F35: 1 | G35: 1 | H35: D | I35: 1 | J35: 0 | K35: H | L35: T Robinson | M35: 21 | N35: 11 | O35: 5 | P35: 3 | Q35: 15 | R35: 18 | S35: 3 | T35: 2 | U35: 2 | V35: 3 | W35: 0 | X35: 0 | Y35: 2.38 | Z35: 3.25 | AA35: 3 | AB35: 2.4 | AC35: 3.6 | AD35: 2.8 | AE35: 2.45 | AF35: 3.4 | AG35: 2.88 | AH35: 2.4 | AI35: 3.53 | AJ35: 2.97 | AK35: 2.5 | AL35: 3.4 | AM35: 2.88 | AN35: 2.49 | AO35: 3.4 | AP35: 3.03 | AQ35: 2.5 | AR35: 3.6 | AS35: 3.03 | AT35: 2.42 | AU35: 3.48 | AV35: 2.92 | AW35: 2.5 | AX35: 3.6 | AY35: 3 | AZ35: 1.73 | BA35: 2.1 | BB35: 1.72 | BC35: 2.18 | BD35: 1.75 | BE35: 2.22 | BF35: 1.72 | BG35: 2.16 | BH35: 1.77 | BI35: 2.24 | BJ35: -0.25 | BK35: 2.08 | BL35: 1.82 | BM35: 2.08 | BN35: 1.81 | BO35: 2.14 | BP35: 1.83 | BQ35: 2.07 | BR35: 1.79 | BS35: 2.17 | BT35: 1.83 | BU35: 2.25 | BV35: 3.3 | BW35: 3.2 | BX35: 2.35 | BY35: 3.4 | BZ35: 3 | CA35: 2.25 | CB35: 3.3 | CC35: 3.1 | CD35: 2.36 | CE35: 3.41 | CF35: 3.21 | CG35: 2.3 | CH35: 3.4 | CI35: 3.2 | CJ35: 2.31 | CK35: 3.39 | CL35: 3.29 | CM35: 2.39 | CN35: 3.45 | CO35: 3.29 | CP35: 2.33 | CQ35: 3.39 | CR35: 3.15 | CS35: 2.4 | CT35: 3.45 | CU35: 3.35 | CV35: 1.86 | CW35: 2.04 | CX35: 1.86 | CY35: 2.05 | CZ35: 1.9 | DA35: 2.1 | DB35: 1.82 | DC35: 2.03 | DD35: 1.91 | DE35: 2.08 | DF35: -0.25 | DG35: 2.04 | DH35: 1.89 | DI35: 2.04 | DJ35: 1.89 | DK35: 2.06 | DL35: 1.9 | DM35: 2 | DN35: 1.86 | DO35: 2.06 | DP35: 1.92
A36: E0 | B36: 14/09/2024 | C36: 0.625 | D36: Liverpool | E36: Nott'm Forest | F36: 0 | G36: 1 | H36: A | I36: 0 | J36: 0 | K36: D | L36: M Oliver | M36: 14 | N36: 5 | O36: 5 | P36: 3 | Q36: 15 | R36: 6 | S36: 7 | T36: 2 | U36: 4 | V36: 4 | W36: 0 | X36: 0 | Y36: 1.22 | Z36: 6.5 | AA36: 12 | AB36: 1.22 | AC36: 7 | AD36: 12 | AE36: 1.2 | AF36: 7 | AG36: 13 | AH36: 1.21 | AI36: 7.23 | AJ36: 12.71 | AK36: 1.22 | AL36: 6.5 | AM36: 13 | AN36: 1.25 | AO36: 6.86 | AP36: 12.4 | AQ36: 1.25 | AR36: 7.7 | AS36: 13 | AT36: 1.22 | AU36: 7.03 | AV36: 12.4 | AW36: 1.24 | AX36: 7.8 | AY36: 14.5 | AZ36: 1.44 | BA36: 2.75 | BB36: 1.41 | BC36: 2.95 | BD36: 1.46 | BE36: 3.1 | BF36: 1.41 | BG36: 2.91 | BH36: 1.47 | BI36: 3.1 | BJ36: -2 | BK36: 2.07 | BL36: 1.83 | BM36: 2.05 | BN36: 1.83 | BO36: 2.09 | BP36: 1.87 | BQ36: 2.03 | BR36: 1.84 | BS36: 2.06 | BT36: 1.9 | BU36: 1.25 | BV36: 6.25 | BW36: 11 | BX36: 1.26 | BY36: 6.5 | BZ36: 10.5 | CA36: 1.2 | CB36: 6.5 | CC36: 12 | CD36: 1.22 | CE36: 7.11 | CF36: 12.95 | CG36: 1.22 | CH36: 6.5 | CI36: 13 | CJ36: 1.27 | CK36: 6.37 | CL36: 11.7 | CM36: 1.27 | CN36: 7.3 | CO36: 13 | CP36: 1.23 | CQ36: 6.75 | CR36: 11.99 | CS36: 1.24 | CT36: 7.6 | CU36: 15.5 | CV36: 1.4 | CW36: 3 | CX36: 1.4 | CY36: 3.06 | CZ36: 1.44 | DA36: 3.06 | DB36: 1.41 | DC36: 2.98 | DD36: 1.43 | DE36: 3.25 | DF36: -1.75 | DG36: 1.86 | DH36: 2.07 | DI36: 1.85 | DJ36: 2.07 | DK36: 1.87 | DL36: 2.11 | DM36: 1.84 | DN36: 2.04 | DO36: 1.87 | DP36: 2.11
A37: E0 | B37: 14/09/2024 | C37: 0.625 | D37: Man City | E37: Brentford | F37: 2 | G37: 1 | H37: H | I37: 2 | J37: 1 | K37: H | L37: D Bond | M37: 18 | N37: 8 | O37: 7 | P37: 5 | Q37: 9 | R37: 3 | S37: 12 | T37: 3 | U37: 3 | V37: 1 | W37: 0 | X37: 0 | Y37: 1.18 | Z37: 8 | AA37: 12 | AB37: 1.19 | AC37: 7.75 | AD37: 14 | AE37: 1.15 | AF37: 9 | AG37: 15 | AH37: 1.17 | AI37: 8.43 | AJ37: 14.62 | AK37: 1.18 | AL37: 7.5 | AM37: 15 | AN37: 1.19 | AO37: 8.1 | AP37: 15 | AQ37: 1.21 | AR37: 9.2 | AS37: 17 | AT37: 1.17 | AU37: 8.2 | AV37: 14.79 | AW37: 1.19 | AX37: 9.6 | AY37: 17.5 | AZ37: 1.36 | BA37: 3.2 | BB37: 1.36 | BC37: 3.17 | BD37: 1.4 | BE37: 3.45 | BF37: 1.35 | BG37: 3.22 | BH37: 1.39 | BI37: 3.4 | BJ37: -2 | BK37: 1.92 | BL37: 1.98 | BM37: 1.91 | BN37: 1.96 | BO37: 1.93 | BP37: 2.11 | BQ37: 1.85 | BR37: 2.02 | BS37: 1.87 | BT37: 2.08 | BU37: 1.17 | BV37: 8 | BW37: 15 | BX37: 1.21 | BY37: 7.5 | BZ37: 12 | CA37: 1.15 | CB37: 8 | CC37: 15 | CD37: 1.21 | CE37: 7.2 | CF37: 13.92 | CG37: 1.2 | CH37: 7 | CI37: 15 | CJ37: 1.18 | CK37: 8.24 | CL37: 16.1 | CM37: 1.22 | CN37: 8.3 | CO37: 16.1 | CP37: 1.19 | CQ37: 7.64 | CR37: 13.85 | CS37: 1.23 | CT37: 7.6 | CU37: 17.5 | CV37: 1.44 | CW37: 2.75 | CX37: 1.45 | CY37: 2.85 | CZ37: 1.45 | DA37: 3.14 | DB37: 1.41 | DC37: 2.96 | DD37: 1.44 | DE37: 3.2 | DF37: -2 | DG37: 2.08 | DH37: 1.85 | DI37: 2.09 | DJ37: 1.81 | DK37: 2.09 | DL37: 1.94 | DM37: 2 | DN37: 1.87 | DO37: 2.04 | DP37: 1.94
A38: E0 | B38: 14/09/2024 | C38: 0.72916667 | D38: Aston Villa | E38: Everton | F38: 3 | G38: 2 | H38: H | I38: 1 | J38: 2 | K38: A | L38: C Pawson | M38: 17 | N38: 6 | O38: 8 | P38: 2 | Q38: 10 | R38: 12 | S38: 6 | T38: 2 | U38: 1 | V38: 4 | W38: 0 | X38: 0 | Y38: 1.5 | Z38: 4.2 | AA38: 6.5 | AB38: 1.5 | AC38: 4.5 | AD38: 6.25 | AE38: 1.47 | AF38: 4.5 | AG38: 6.5 | AH38: 1.51 | AI38: 4.45 | AJ38: 6.48 | AK38: 1.5 | AL38: 4.4 | AM38: 6.5 | AN38: 1.54 | AO38: 4.63 | AP38: 6.3 | AQ38: 1.55 | AR38: 4.65 | AS38: 6.7 | AT38: 1.51 | AU38: 4.48 | AV38: 6.34 | AW38: 1.54 | AX38: 4.7 | AY38: 7 | AZ38: 1.67 | BA38: 2.2 | BB38: 1.69 | BC38: 2.23 | BD38: 1.72 | BE38: 2.28 | BF38: 1.67 | BG38: 2.23 | BH38: 1.73 | BI38: 2.32 | BJ38: -1 | BK38: 1.85 | BL38: 2.05 | BM38: 1.87 | BN38: 2.02 | BO38: 1.88 | BP38: 2.1 | BQ38: 1.84 | BR38: 2.03 | BS38: 1.88 | BT38: 2.08 | BU38: 1.67 | BV38: 3.75 | BW38: 5.25 | BX38: 1.68 | BY38: 3.9 | BZ38: 5 | CA38: 1.57 | CB38: 4.2 | CC38: 5.5 | CD38: 1.68 | CE38: 4 | CF38: 5.44 | CG38: 1.67 | CH38: 4 | CI38: 5 | CJ38: 1.69 | CK38: 3.84 | CL38: 5.64 | CM38: 1.72 | CN38: 4.2 | CO38: 5.64 | CP38: 1.68 | CQ38: 3.94 | CR38: 5.24 | CS38: 1.72 | CT38: 4.1 | CU38: 5.5 | CV38: 1.8 | CW38: 2 | CX38: 1.82 | CY38: 2.08 | CZ38: 1.84 | DA38: 2.21 | DB38: 1.78 | DC38: 2.07 | DD38: 1.84 | DE38: 2.18 | DF38: -0.75 | DG38: 1.88 | DH38: 2.05 | DI38: 1.87 | DJ38: 2.06 | DK38: 1.91 | DL38: 2.08 | DM38: 1.85 | DN38: 2.02 | DO38: 1.91 | DP38: 2.07
A39: E0 | B39: 14/09/2024 | C39: 0.83333333 | D39: Bournemouth | E39: Chelsea | F39: 0 | G39: 1 | H39: A | I39: 0 | J39: 0 | K39: D | L39: A Taylor | M39: 19 | N39: 10 | O39: 7 | P39: 3 | Q39: 16 | R39: 9 | S39: 6 | T39: 3 | U39: 6 | V39: 8 | W39: 0 | X39: 0 | Y39: 3.4 | Z39: 3.8 | AA39: 2 | AB39: 3.3 | AC39: 3.9 | AD39: 2.05 | AE39: 3.4 | AF39: 3.9 | AG39: 2 | AH39: 3.32 | AI39: 3.97 | AJ39: 2.06 | AK39: 3.4 | AL39: 3.9 | AM39: 2.05 | AN39: 3.4 | AO39: 4.12 | AP39: 2.05 | AQ39: 3.45 | AR39: 4.12 | AS39: 2.09 | AT39: 3.33 | AU39: 3.96 | AV39: 2.05 | AW39: 3.55 | AX39: 4.1 | AY39: 2.08 | AZ39: 1.44 | BA39: 2.75 | BB39: 1.46 | BC39: 2.81 | BD39: 1.48 | BE39: 2.86 | BF39: 1.45 | BG39: 2.76 | BH39: 1.49 | BI39: 2.94 | BJ39: 0.5 | BK39: 1.85 | BL39: 2.05 | BM39: 1.83 | BN39: 2.07 | BO39: 1.87 | BP39: 2.08 | BQ39: 1.83 | BR39: 2.03 | BS39: 1.9 | BT39: 2.08 | BU39: 3.1 | BV39: 3.6 | BW39: 2.2 | BX39: 2.95 | BY39: 3.75 | BZ39: 2.25 | CA39: 3.2 | CB39: 3.8 | CC39: 2 | CD39: 3.17 | CE39: 3.79 | CF39: 2.23 | CG39: 3 | CH39: 3.9 | CI39: 2.2 | CJ39: 3.27 | CK39: 3.69 | CL39: 2.21 | CM39: 3.36 | CN39: 4 | CO39: 2.28 | CP39: 3.11 | CQ39: 3.8 | CR39: 2.19 | CS39: 3.15 | CT39: 3.95 | CU39: 2.28 | CV39: 1.5 | CW39: 2.63 | CX39: 1.5 | CY39: 2.7 | CZ39: 1.52 | DA39: 2.98 | DB39: 1.47 | DC39: 2.73 | DD39: 1.51 | DE39: 2.92 | DF39: 0.25 | DG39: 1.95 | DH39: 1.98 | DI39: 1.97 | DJ39: 1.95 | DK39: 2.07 | DL39: 1.99 | DM39: 1.95 | DN39: 1.92 | DO39: 1.99 | DP39: 1.99
A40: E0 | B40: 15/09/2024 | C40: 0.58333333 | D40: Tottenham | E40: Arsenal | F40: 0 | G40: 1 | H40: A | I40: 0 | J40: 0 | K40: D | L40: J Gillett | M40: 15 | N40: 7 | O40: 5 | P40: 4 | Q40: 13 | R40: 10 | S40: 7 | T40: 6 | U40: 5 | V40: 3 | W40: 0 | X40: 0 | Y40: 3 | Z40: 3.5 | AA40: 2.3 | AB40: 2.95 | AC40: 3.7 | AD40: 2.25 | AE40: 2.9 | AF40: 3.6 | AG40: 2.3 | AH40: 3.03 | AI40: 3.62 | AJ40: 2.32 | AK40: 3 | AL40: 3.6 | AM40: 2.3 | AN40: 3.13 | AO40: 3.46 | AP40: 2.4 | AQ40: 3.13 | AR40: 3.75 | AS40: 2.4 | AT40: 2.99 | AU40: 3.59 | AV40: 2.33 | AW40: 3.1 | AX40: 3.75 | AY40: 2.4 | AZ40: 1.57 | BA40: 2.38 | BB40: 1.59 | BC40: 2.44 | BD40: 1.66 | BE40: 2.5 | BF40: 1.58 | BG40: 2.41 | BH40: 1.65 | BI40: 2.5 | BJ40: 0.25 | BK40: 1.88 | BL40: 2.02 | BM40: 1.86 | BN40: 2.02 | BO40: 1.93 | BP40: 2.05 | BQ40: 1.84 | BR40: 2 | BS40: 1.9 | BT40: 2.08 | BU40: 2.7 | BV40: 3.4 | BW40: 2.6 | BX40: 2.7 | BY40: 3.5 | BZ40: 2.5 | CA40: 2.75 | CB40: 3.4 | CC40: 2.4 | CD40: 2.77 | CE40: 3.49 | CF40: 2.63 | CG40: 2.62 | CH40: 3.75 | CI40: 2.5 | CJ40: 3 | CK40: 3.49 | CL40: 2.43 | CM40: 3 | CN40: 3.75 | CO40: 2.63 | CP40: 2.77 | CQ40: 3.51 | CR40: 2.53 | CS40: 2.84 | CT40: 3.6 | CU40: 2.66 | CV40: 1.62 | CW40: 2.3 | CX40: 1.68 | CY40: 2.29 | CZ40: 1.68 | DA40: 2.45 | DB40: 1.61 | DC40: 2.37 | DD40: 1.65 | DE40: 2.5 | DF40: 0 | DG40: 2.01 | DH40: 1.92 | DI40: 2.01 | DJ40: 1.89 | DK40: 2.09 | DL40: 1.93 | DM40: 2.01 | DN40: 1.88 | DO40: 2.05 | DP40: 1.95
...

Sheet Raw_data 
A4: Date | B4: HomeTeam | C4: AwayTeam | D4: FTHG | E4: FTAG | F4: FTR | G4: HTHG | H4: HTAG | I4: HS | J4: AS | K4: HST | L4: AST | M4: HF | N4: AF | O4: HC | P4: AC
A5: 45520 | B5: Man United | C5: Fulham | D5: 1 | E5: 0 | F5: H | G5: 0 | H5: 0 | I5: 14 | J5: 10 | K5: 5 | L5: 2 | M5: 12 | N5: 10 | O5: 7 | P5: 8
A6: 45521 | B6: Ipswich | C6: Liverpool | D6: 0 | E6: 2 | F6: A | G6: 0 | H6: 0 | I6: 7 | J6: 18 | K6: 2 | L6: 5 | M6: 9 | N6: 18 | O6: 2 | P6: 10
A7: 45521 | B7: Arsenal | C7: Wolves | D7: 2 | E7: 0 | F7: H | G7: 1 | H7: 0 | I7: 18 | J7: 9 | K7: 6 | L7: 3 | M7: 17 | N7: 14 | O7: 8 | P7: 2
A8: 45521 | B8: Everton | C8: Brighton | D8: 0 | E8: 3 | F8: A | G8: 0 | H8: 1 | I8: 9 | J8: 10 | K8: 1 | L8: 5 | M8: 8 | N8: 8 | O8: 1 | P8: 5
A9: 45521 | B9: Newcastle | C9: Southampton | D9: 1 | E9: 0 | F9: H | G9: 1 | H9: 0 | I9: 3 | J9: 19 | K9: 1 | L9: 4 | M9: 15 | N9: 16 | O9: 3 | P9: 12
A10: 45521 | B10: Nott'm Forest | C10: Bournemouth | D10: 1 | E10: 1 | F10: D | G10: 1 | H10: 0 | I10: 14 | J10: 13 | K10: 8 | L10: 4 | M10: 17 | N10: 8 | O10: 2 | P10: 6
A11: 45521 | B11: West Ham | C11: Aston Villa | D11: 1 | E11: 2 | F11: A | G11: 1 | H11: 1 | I11: 14 | J11: 15 | K11: 3 | L11: 3 | M11: 18 | N11: 11 | O11: 5 | P11: 3
A12: 45522 | B12: Brentford | C12: Crystal Palace | D12: 2 | E12: 1 | F12: H | G12: 1 | H12: 0 | I12: 9 | J12: 14 | K12: 5 | L12: 6 | M12: 6 | N12: 15 | O12: 4 | P12: 7
A13: 45522 | B13: Chelsea | C13: Man City | D13: 0 | E13: 2 | F13: A | G13: 0 | H13: 1 | I13: 10 | J13: 11 | K13: 3 | L13: 5 | M13: 12 | N13: 9 | O13: 4 | P13: 3
A14: 45523 | B14: Leicester | C14: Tottenham | D14: 1 | E14: 1 | F14: D | G14: 0 | H14: 1 | I14: 7 | J14: 15 | K14: 3 | L14: 7 | M14: 11 | N14: 12 | O14: 2 | P14: 13
A15: 45528 | B15: Brighton | C15: Man United | D15: 2 | E15: 1 | F15: H | G15: 1 | H15: 0 | I15: 14 | J15: 11 | K15: 5 | L15: 4 | M15: 9 | N15: 13 | O15: 4 | P15: 4
A16: 45528 | B16: Crystal Palace | C16: West Ham | D16: 0 | E16: 2 | F16: A | G16: 0 | H16: 0 | I16: 14 | J16: 18 | K16: 2 | L16: 3 | M16: 9 | N16: 17 | O16: 3 | P16: 3
... A384: 45802 | B384: Wolves | C384: Brentford | D384: 1 | E384: 1 | F384: D | G384: 0 | H384: 1 | I384: 18 | J384: 13 | K384: 6 | L384: 7 | M384: 7 | N384: 9 | O384: 8 | P384: 3

Sheet Team_Match_Data
A4: Date | B4: Team | C4: Opponent | D4: Goals for | E4: Goals against | F4: FTR | G4: Shots | H4: Shots_on_target | I4: Venue | J4: Points | K4: Results
A5: 45520 | B5: Man United | C5: Fulham | D5: 1 | E5: 0 | F5: H | G5: 14 | H5: 5 | I5: Home | J5: 3 | K5: W
